Workbook

Sheet README
A1: TSPi Team Workbook - TMA3084 Software Engineering Laboratory
A2: Faculty of Computer Science & Information Technology, UNIMAS | Semester 1, Session 2026/2027 | Workbook v3.0 (2026-10-29)
B3: WORKED SAMPLE - all names, matric numbers, emails, phone numbers and the client are fictional. The time, task and defect data is migrated from a real past team's workbooks with identities removed; the test, AI, client, GitHub and evaluation forms are illustrative, written to show what a complete workbook looks like. Do not copy the numbers - copy the habit.
B4: What this is | C4: A Team Software Process (TSP) team workbook rebuilt for TMA3084. It keeps the TSP measurement discipline - time, defects, size, earned value - and adds the forms this course actually assesses: AI-assisted coding, automated testing, GitHub workflow, client engagement and peer evaluation.
B5: Lineage | C5: The process model follows the Team Software Process introduced by Watts S. Humphrey. The original TSPi support workbook (2002, Addison-Wesley) is the ancestor of this file; every sheet here has been rewritten for this course. Forms, phases, defect types and all guidance text are original to TMA3084.
B6: What changed from the 2002 workbook | C6: NEW forms: LOGAI (AI-assisted development), LOGTEST (test cases), LOGCLIENT (client meetings), LOGGIT (GitHub activity), CCR (change requests), PEER, TEAMEVAL, ASSESS, DASHBOARD, FORM-SI. MODERNISED: phase set now covers AI generation, pull-request review, static analysis, widget test and CI/CD; defect types extended with UI/Layout, State Management, Performance, Security and AI-Generated; size measures cover screens, widgets and API endpoints alongside LOC. REMOVED: the single-week WEEK form is now a 13-week tracking table, and the PSP-style prediction intervals are dropped as the team has no historical data base.
B7: Colour convention | C7: AMBER cells are yours to fill in. GREY cells are calculated - typing over one destroys the rollup. Every drop-down is fed by the LISTS sheet.
B8: How to run it | C8: 1. Fill SETUP once, then FORM-SI with every member. 2. Agree roles in ROLES and goals in GOALS. 3. Plan each cycle in TASK and SCHEDULE. 4. Record daily in LOGT, LOGD, LOGTEST and LOGAI. 5. Hold the weekly meeting against WEEK and IRTL. 6. SUMP, SUMQ, SUMS and DASHBOARD fill themselves.
B9: One workbook per team | C9: The team keeps one shared copy in the repository (docs/tspi/). Each member records their own rows in the logs and tags them with their name, so individual contribution is traceable without separate files.
B10: Honesty clause | C10: These numbers are the evidence behind Peer/Individual and Team Evaluation. Logging work you did not do, or back-filling a term's worth of hours the night before a milestone, is academic dishonesty and the pattern is visible in DASHBOARD.
A12: Milestones
B13: Milestone | C13: Week / Due | D13: Deliverables
B14: M1 Proposal & Planning (10%) | C14: Week 5 - due 25 Oct 2026 | Proposal, SRS draft, GitHub repo, Team Charter, client approval, >=2 client meetings
B15: M2 Requirements & Design (15%) | C15: Week 9 - due 20 Nov 2026 | Revised SRS, SDD, Flutter prototype (4-5 screens), >=10 LOGAI entries, test plan (>=20 cases), >=4 client meetings
B16: M3 Implementation & Testing (35%) | C16: Week 13 - due 20 Dec 2026 | Final SDD, >=50 tests at >=60% coverage, GitHub Actions green, APK/IPA build, >=6 client meetings
B17: M4 Release & Oral Commitment (40%) | C17: Week 15 - due 02 Jan 2027 | Final report, user manual, demo video 5-10 min, presentation, client sign-off, v1.0.0 release

Sheet MANUAL
A1: How to Use This Workbook
A2: TMA3084 Software Engineering Laboratory - a step-by-step manual for the team. Read this once, together, at the launch meeting.
A4: 1. What this workbook is
B5: The short version | C5: This is a Team Software Process (TSP) workbook. TSP is a way of running a software project where the team plans its own work, measures what actually happens, and uses those measurements to plan better next time. The workbook is where the measuring happens.
B6: Why bother | C6: Three questions decide most student projects: are we going to finish on time, is the thing we are building any good, and is everyone actually contributing. Opinions on all three are usually wrong. This workbook answers them with data the team collected itself.
B7: The four things you record | C7: TIME - how long work actually took, not how long it felt. SIZE - how much you built. DEFECTS - every mistake found, and the phase where it was made. STATUS - which tasks are finished. Everything else on the summary sheets is arithmetic on those four.
B8: What it is not | C8: It is not a surveillance tool and it is not graded on neatness. Nobody is marked down for a high defect count - a team recording 40 defects is doing better engineering than an identical team recording 3, because the second team is not looking. What does get noticed is a log that is empty, or one filled in all at once the night before a milestone.
A10: 2. Before you start - conventions
B11: Convention | C11: What it means
B12: Amber cells | C12: You type here. Everything the team knows goes into an amber cell.
B13: Grey cells | C13: Calculated. Typing over one breaks the rollups that depend on it - if a grey number looks wrong, the log feeding it is wrong, so fix the log.
B14: Drop-downs | C14: Fed by the LISTS sheet. Member names come from FORM-SI, so fill FORM-SI first or every name drop-down in the workbook will be empty.
B15: Red / amber / green | C15: Applied automatically. Red is not a punishment, it is a prompt to talk about something at the next meeting.
B16: Hover for help | C16: Cells with a small red corner marker carry a note explaining what goes in them.
B17: Reference sheets | C17: PHASES and DEFECTTYPES are the standards you code against - read them in Week 1. PLANGUIDE and QUALGUIDE tell you what to aim for. None of the four should ever be edited.
B18: Charts | C18: PROJECT and CHARTS draw themselves from the logs. There is no Draw button and nothing to refresh - if a chart is empty, the log behind it is empty.
A20: 3. Stage one - the launch (do this in Week 1, and again at the start of every cycle)
A21: # | B21: Step | C21: What to do | D21: Form | E21: Who / when
A22: 1 | B22: Fill in SETUP | C22: Course details, team name, project title, client, repository URL and team size. Then check the milestone dates against the course outline and set the thresholds. Every other sheet reads its header from here, so this is the one place you type the team name. | D22: SETUP | E22: Team Leader, Week 1
A23: 2 | B23: Enter every member | C23: One row per member in FORM-SI: matric number, full name, UNIMAS email, GitHub handle. The name you type here is the name that appears in every drop-down, so agree on a spelling and do not change it later. | D23: FORM-SI | E23: All members, Week 1
A24: 3 | B24: Write the team charter | C24: The lower half of FORM-SI. Six short answers: vision, communication norms, definition of done, conflict resolution, quality standards, expected hours. Write these before you disagree about them, not after. | D24: FORM-SI | E24: Team, Week 1
A25: 4 | B25: Assign roles | C25: There are six roles and five of you, so one member holds two this cycle and nobody holds more than two. The double rotates, and nobody keeps the same role for more than two milestones running. The Role Load Check at the bottom of the sheet adds this up for you. A role is real work, not a title. | D25: ROLES | E25: Team Leader, each launch
A26: 5 | B26: Set measurable goals | C26: A goal needs a number and an owner or it is a wish. Seven starter goals are listed at the bottom of the sheet; replace them with your own. | D26: GOALS | E26: Team, each launch
A27: 6 | B27: Agree the strategy | C27: What each cycle actually delivers, what you build versus reuse, the main technical risk and who owns it. Then record the stack decisions and why - the Design rubric asks you to justify alternatives considered. | D27: STRAT | E27: Dev Manager, each launch
A28: 7 | B28: Size what you are building | C28: List the screens, modules and documents in SUMS with a planned size. Estimates will be wrong early on. Record them anyway - a wrong estimate you measured against is worth more than no estimate. | D28: SUMS | E28: Planning Manager
A29: 8 | B29: Break the work into tasks | C29: Tasks of roughly 2 to 10 hours, each with one owner, a phase, planned hours and a planned week. A task bigger than 10 hours is hiding something. | D29: TASK | E29: Planning Manager
A30: 9 | B30: Spread it across the weeks | C30: Put the hours each week in SCHEDULE. Check the Difference cell at the top: schedule hours must match task hours. If they do not, one of the two plans is fiction. | D30: SCHEDULE | E30: Planning Manager
A32: 4. Stage two - daily discipline (the habit that makes everything else work)
A33: # | B33: Step | C33: What to do | D33: Form | E33: Who / when
A34: 10 | B34: Log time as you work | C34: Start a LOGT row when you sit down, fill in the stop time when you get up. Subtract interruptions honestly. Reconstructing a week of hours from memory produces numbers that are worse than useless, because they look real. | D34: LOGT | E34: Every member, daily
A35: 11 | B35: Tag the task | C35: Put the Task ID from TASK in the Task ID column. That is what makes hours roll up against the plan. Unplanned work with no ID is fine - add the task to TASK afterwards so the plan stays honest. | D35: LOGT | E35: Every member, daily
A36: 12 | B36: Log every defect | C36: Anything wrong that you had to fix, including the ones you found yourself within a minute. The hard column is Injected in: the phase where the mistake was MADE, not where you noticed it. Getting that right is the whole point. | D36: LOGD | E36: Every member, daily
A37: 13 | B37: Log every test | C37: One row per test case with its type and status. Automated tests get a row too - LOGTEST is the evidence behind the Testing and Release rubric, not a duplicate of your test files. | D37: LOGTEST | E37: Quality & Test Manager, daily
A38: 14 | B38: Log every AI-assisted change | C38: Any time Copilot, Claude or another generator wrote code that reached the repository: what you asked for, how many lines it gave you, how many survived review, who reviewed it, and whether tests were written. The reviewer must not be you - the sheet turns that row red. | D38: LOGAI | E38: Every member, each change
A39: 15 | B39: Record client meetings | C39: Date, mode, who attended, what was decided, what actions came out and who owns them. Keep the minutes or a photo as evidence. The milestones require 2, 4 and 6 cumulative meetings - this is how you prove it. | D39: LOGCLIENT | E39: Product Owner
A41: 5. Stage three - the weekly meeting (about 30 minutes, same time every week)
A42: # | B42: Step | C42: What to do | D42: Form | E42: Who / when
A43: 16 | B43: Pull the GitHub numbers | C43: Commits, pull requests, reviews and issues closed per member, read from the repository Insights tab. These are facts - do not estimate them. | D43: LOGGIT | E43: Support Manager, weekly
A44: 17 | B44: Update task status | C44: Mark finished tasks Complete. Earned value is only credited for completed tasks; a task that is 90% done earns nothing. That is deliberate - it is what stops a plan from slipping quietly. | D44: TASK | E44: Planning Manager, weekly
A45: 18 | B45: Read the week's numbers | C45: WEEK fills itself from SCHEDULE. Look at EV variance: negative means the team has delivered less than it planned by this week, however many hours it has burned. Hours are effort; earned value is progress. | D45: WEEK | E45: Team Leader, weekly
...

Sheet INDEX
A1: Index of Forms
A2: Click a form name to jump to it.
A4: Start here
B5: Form | C5: What it is for | D5: Owner | E5: When
B6: MANUAL | C6: Step-by-step manual: what to do, when, and on which form | D6: Read at launch | E6: Week 1
B7: PROJECT | C7: Project summary: headline numbers and the two charts that matter most | D7: Automatic | E7: Always
A9: Launch - do these once, at the start of each cycle
B10: Form | C10: What it is for | D10: Owner | E10: When
B11: SETUP | C11: Course, team, client, repository and the milestone plan | D11: Team Leader | E11: Week 1
B12: FORM-SI | C12: Member details, contribution rollup and the team charter | D12: All members | E12: Week 1
B13: ROLES | C13: Who holds which of the six TSP roles in each milestone | D13: Team Leader | E13: Each launch
B14: GOALS | C14: Measurable team goals with owners and review dates | D14: Team | E14: Each launch
B15: STRAT | C15: What each cycle delivers, and the stack decisions behind it | D15: Dev Manager | E15: Each launch
A17: Plan - the commitment the team makes
B18: Form | C18: What it is for | D18: Owner | E18: When
B19: TASK | C19: Task plan, estimates, ownership and earned value | D19: Planning Manager | E19: Each launch
B20: SCHEDULE | C20: Hours per week, planned against earned value | D20: Planning Manager | E20: Each launch
A22: Record - fill these as the work happens, not afterwards
B23: Form | C23: What it is for | D23: Owner | E23: When
B24: LOGT | C24: Time recording log - one row per working session | D24: All members | E24: Daily
B25: LOGD | C25: Defect recording log - every defect, wherever found | D25: All members | E25: Daily
B26: LOGTEST | C26: Test case log with status, type and coverage evidence | D26: Quality & Test Mgr | E26: Daily
B27: LOGAI | C27: AI-assisted development log with reviewer and verdict | D27: All members | E27: Every AI change
B28: LOGCLIENT | C28: Client meetings, decisions, actions and sign-off | D28: Product Owner | E28: Each meeting
B29: LOGGIT | C29: Weekly GitHub activity read from repository Insights | D29: Support Manager | E29: Weekly
A31: Track - the weekly rhythm
B32: Form | C32: What it is for | D32: Owner | E32: When
B33: WEEK | C33: Weekly status: hours, earned value, risk and commitment | D33: Team Leader | E33: Weekly
B34: IRTL | C34: Issue and risk tracking with likelihood, impact and owner | D34: Team Leader | E34: Weekly
B35: IRWEEK | C35: How the risk picture moved week by week - raised, closed, still open | D35: Team Leader | E35: Weekly
B36: RISK | C36: The top open risks from IRTL, ranked by priority | D36: Automatic | E36: Weekly
B37: CCR | C37: Change requests against an agreed baseline | D37: Support Manager | E37: As needed
A39: Summarise - these calculate themselves
B40: Form | C40: What it is for | D40: Owner | E40: When
B41: SUMS | C41: Size summary for components and documents | D41: Planning Manager | E41: Each milestone
B42: SUMP | C42: Plan summary: size, time in phase, defects injected and removed | D42: Planning Manager | E42: Each milestone
B43: SUMQ | C43: Quality summary: density, yield, review rates, test quality | D43: Quality & Test Mgr | E43: Each milestone
B44: CHARTS | C44: The fourteen TSP charts, drawn from your own logs | D44: Automatic | E44: Always
A46: Evaluate - the assessed forms
B47: Form | C47: What it is for | D47: Owner | E47: When
...

Sheet PROJECT
A1: Project Summary
A2: The one page to open first. Everything here is calculated from the logs.
B4: Project | C4: =SETUP!$C$11 | E4: Report date | G4: =TODAY()
B5: Team | C5: =SETUP!$C$10 | E5: Current week | G5: =CHARTDATA!$D$4
B6: Client | C6: =SETUP!$C$12 | E6: Team size | G6: =SETUP!$C$16
B7: Instructor | C7: =SETUP!$C$7 | E7: Repository | G7: =SETUP!$C$14
A9: Headline Measures
B10: Planned hours | C10: Actual hours | D10: Planned value to date | E10: Earned value to date | F10: New & changed LOC | G10: Defects removed | H10: Defects / KLOC | I10: Test cases | J10: Test pass rate
B11: =SUM(TASK!$K$8:$K$127) | C11: =SUM(LOGT!$K$7:$K$406)/60 | D11: =CHARTDATA!$G$19 | E11: =CHARTDATA!$I$19 | F11: =SUMP!$C$10 | G11: =SUMP!$C$96 | H11: =IFERROR(SUMP!$C$96/(SUMP!$C$10/1000),"") | I11: =COUNTA(LOGTEST!$A$7:$A$306) | J11: =IFERROR(COUNTIF(LOGTEST!$H$7:$H$306,"Pass")/COUNTA(LOGTEST!$H$7:$H$306),"")
A13: Earned Value and Effort
A32: Where the team stands
B33: =IF(CHARTDATA!$I$19-CHARTDATA!$G$19<-0.1,"BEHIND - earned value is more than ten points below plan. Look at TASK for work that is started but not finished, and at DASHBOARD for who is carrying the load.",IF(CHARTDATA!$I$19-CHARTDATA!$G$19<-0.02,"AT RISK - slightly behind plan. Recoverable this week if the team finishes what it started.","ON TRACK - earned value is at or ahead of plan. Keep logging; the picture is only as good as the data behind it."))

Sheet SETUP
A1: Project Setup
A2: Fill this sheet once at team launch. Every other form reads from here.
A4: Team & Project Identification
B5: Course | C5: TMA3084 Software Engineering Laboratory
B6: Semester | C6: Semester 1, Session 2026/2027
B7: Instructor | C7: Ts. Nurfauza Jali
B8: Lab Demonstrator | C8: Mr. MD. Aminul Islam Rakib
B9: Lab Group (1 or 2) | C9: 1
B10: Team Name / Number | C10: AUV
B11: Project Title | C11: SeaFresh Supplier Mobile App
B12: Client Organisation | C12: SeaFresh Seafood Trading (sample client)
B13: Client Contact & Email | C13: Encik Faizal (sample) - faizal@seafresh.example
B14: GitHub Repository URL | C14: https://github.com/tma3084-sample/auv-seafresh
B15: Project Board URL | C15: https://github.com/orgs/tma3084-sample/projects/1
B16: Team Size | C16: 5
A18: Milestone Plan
A19: ID | B19: Milestone | C19: Week | D19: Start | E19: Due | F19: Weight | G19: Status | H19: Key Deliverables
A20: M1 | B20: Proposal & Planning | C20: 5 | D20: 46314 | E20: 46320 | F20: 0.1 | G20: Complete | H20: Proposal, SRS draft, GitHub repo, Team Charter, client approval, >=2 client meetings
A21: M2 | B21: Requirements & Design | C21: 9 | D21: 46342 | E21: 46346 | F21: 0.15 | G21: Complete | H21: Revised SRS, SDD, Flutter prototype (4-5 screens), >=10 LOGAI entries, test plan (>=20 cases), >=4 client meetings
A22: M3 | B22: Implementation & Testing | C22: 13 | D22: 46370 | E22: 46376 | F22: 0.35 | G22: Complete | H22: Final SDD, >=50 tests at >=60% coverage, GitHub Actions green, APK/IPA build, >=6 client meetings
A23: M4 | B23: Release & Oral Commitment | C23: 15 | D23: 46384 | E23: 46389 | F23: 0.4 | G23: In progress | H23: Final report, user manual, demo video 5-10 min, presentation, client sign-off, v1.0.0 release
A25: Course Thresholds (used by DASHBOARD to flag a team that is behind)
A26: Threshold | B26: M1 | C26: M2 | D26: M3 | E26: M4 | H26: Notes
A27: Minimum commits (cumulative) | B27: 15 | C27: 30 | D27: 50 | E27: 70 | H27: Git history, all branches merged to develop
A28: Minimum pull requests merged | B28: 3 | C28: 8 | D28: 15 | E28: 20 | H28: Every PR needs at least one reviewer approval
A29: Minimum client meetings (cumulative) | B29: 2 | C29: 4 | D29: 6 | E29: 7 | H29: Logged in LOGCLIENT with client sign-off
A30: Minimum LOGAI entries (cumulative) | B30: 2 | C30: 10 | D30: 15 | E30: 18 | H30: Every AI-assisted change reviewed and logged
A31: Minimum test cases (cumulative) | B31: 0 | C31: 20 | D31: 50 | E31: 60 | H31: LOGTEST; unit + widget + integration
A32: Minimum code coverage | B32: 0 | C32: 0.3 | D32: 0.6 | E32: 0.6 | H32: Critical business logic; from coverage report
A33: Minimum hours per member (cumulative) | B33: 15 | C33: 40 | D33: 80 | E33: 100 | H33: LOGT; flags under-contribution

Sheet FORM-SI
A1: Form SI - Student & Team Information
A2: One row per member. Names entered here feed every drop-down in the workbook.
B4: Team | C4: =SETUP!$C$10 | E4: Project | F4: =SETUP!$C$11
B5: Repository | C5: =SETUP!$C$14 | E5: Client | F5: =SETUP!$C$12
A7: Team Members
A8: # | B8: Matric No. | C8: Full Name | D8: UNIMAS Email | E8: Phone | F8: GitHub Handle | G8: Primary Role | H8: Secondary Role | I8: Plan Hrs | J8: Actual Hrs | K8: Share of Team Hrs | L8: Flag
A9: 1 | B9: 90001 | C9: Aisyah Binti Rahman | D9: 90001@siswa.unimas.my | E9: 011-2000 0001 | F9: aisyah-r | G9: Team Leader | H9: Support Manager | I9: =IF($C9="","",SUMIFS(TASK!$K$8:$K$127,TASK!$F$8:$F$127,$C9)) | J9: =IF($C9="","",SUMIFS(LOGT!$K$7:$K$406,LOGT!$B$7:$B$406,$C9)/60) | K9: =IF(OR($C9="",$J$15=0),"",$J9/$J$15) | L9: =IF($C9="","",IF($J9=0,"NO DATA",IF($K9<0.6/MAX(1,COUNTA($C$9:$C$14)),"LOW",IF($K9>1.6/MAX(1,COUNTA($C$9:$C$14)),"HIGH","OK"))))
A10: 2 | B10: 90002 | C10: Daniel Wong Jun Hao | D10: 90002@siswa.unimas.my | E10: 011-2000 0002 | F10: danielwjh | G10: Development Manager | I10: =IF($C10="","",SUMIFS(TASK!$K$8:$K$127,TASK!$F$8:$F$127,$C10)) | J10: =IF($C10="","",SUMIFS(LOGT!$K$7:$K$406,LOGT!$B$7:$B$406,$C10)/60) | K10: =IF(OR($C10="",$J$15=0),"",$J10/$J$15) | L10: =IF($C10="","",IF($J10=0,"NO DATA",IF($K10<0.6/MAX(1,COUNTA($C$9:$C$14)),"LOW",IF($K10>1.6/MAX(1,COUNTA($C$9:$C$14)),"HIGH","OK"))))
A11: 3 | B11: 90003 | C11: Mei Ling Chong | D11: 90003@siswa.unimas.my | E11: 011-2000 0003 | F11: meiling-c | G11: Planning Manager | I11: =IF($C11="","",SUMIFS(TASK!$K$8:$K$127,TASK!$F$8:$F$127,$C11)) | J11: =IF($C11="","",SUMIFS(LOGT!$K$7:$K$406,LOGT!$B$7:$B$406,$C11)/60) | K11: =IF(OR($C11="",$J$15=0),"",$J11/$J$15) | L11: =IF($C11="","",IF($J11=0,"NO DATA",IF($K11<0.6/MAX(1,COUNTA($C$9:$C$14)),"LOW",IF($K11>1.6/MAX(1,COUNTA($C$9:$C$14)),"HIGH","OK"))))
A12: 4 | B12: 90004 | C12: Harith Bin Ismail | D12: 90004@siswa.unimas.my | E12: 011-2000 0004 | F12: harith-i | G12: Product Owner | I12: =IF($C12="","",SUMIFS(TASK!$K$8:$K$127,TASK!$F$8:$F$127,$C12)) | J12: =IF($C12="","",SUMIFS(LOGT!$K$7:$K$406,LOGT!$B$7:$B$406,$C12)/60) | K12: =IF(OR($C12="",$J$15=0),"",$J12/$J$15) | L12: =IF($C12="","",IF($J12=0,"NO DATA",IF($K12<0.6/MAX(1,COUNTA($C$9:$C$14)),"LOW",IF($K12>1.6/MAX(1,COUNTA($C$9:$C$14)),"HIGH","OK"))))
A13: 5 | B13: 90005 | C13: Priya Nair | D13: 90005@siswa.unimas.my | E13: 011-2000 0005 | F13: priyanair | G13: Quality & Test Manager | I13: =IF($C13="","",SUMIFS(TASK!$K$8:$K$127,TASK!$F$8:$F$127,$C13)) | J13: =IF($C13="","",SUMIFS(LOGT!$K$7:$K$406,LOGT!$B$7:$B$406,$C13)/60) | K13: =IF(OR($C13="",$J$15=0),"",$J13/$J$15) | L13: =IF($C13="","",IF($J13=0,"NO DATA",IF($K13<0.6/MAX(1,COUNTA($C$9:$C$14)),"LOW",IF($K13>1.6/MAX(1,COUNTA($C$9:$C$14)),"HIGH","OK"))))
A14: 6 | I14: =IF($C14="","",SUMIFS(TASK!$K$8:$K$127,TASK!$F$8:$F$127,$C14)) | J14: =IF($C14="","",SUMIFS(LOGT!$K$7:$K$406,LOGT!$B$7:$B$406,$C14)/60) | K14: =IF(OR($C14="",$J$15=0),"",$J14/$J$15) | L14: =IF($C14="","",IF($J14=0,"NO DATA",IF($K14<0.6/MAX(1,COUNTA($C$9:$C$14)),"LOW",IF($K14>1.6/MAX(1,COUNTA($C$9:$C$14)),"HIGH","OK"))))
H15: TEAM TOTAL | I15: =SUM(I9:I14) | J15: =SUM(J9:J14) | K15: =IF($J$15=0,"",1)
A17: Team Charter (agree in Week 1, revisit at every launch)
B18: Team vision | C18: Give SeaFresh's counter staff a phone app that replaces the paper order book, so an order reaches the kitchen without being re-typed.
B19: Communication norms | C19: WhatsApp group for day-to-day, GitHub Issues for anything that needs a record. Replies within 12 hours on weekdays. Stand-up every Wednesday 4pm in the lab; client meeting every second Saturday.
B20: Definition of done | C20: Merged to develop, reviewed and approved by someone other than the author, tests written and passing, CI green, and the LOGAI row filled in if a generator touched it.
B21: Conflict resolution | C21: Raise it in the Wednesday meeting first. If the team cannot settle it, the Team Leader decides and records the reason in IRTL. Nobody re-opens a settled decision without new information.
B22: Quality standards | C22: 60% coverage on business logic, zero analyzer warnings on develop, code review within 24 hours, and no AI-generated code merged without a second pair of eyes.
B23: Commitment | C23: About 10 hours per person per week. Tell the team in advance if you will be away; an unexplained silent week gets raised at the next meeting.

Sheet ROLES
A1: Role Assignment Matrix
A2: Six roles, five of you. One member doubles up each cycle and the double rotates, so everyone leads something.
A4: Team | B4: =SETUP!$C$10
A6: Roles by Milestone
A7: Role | B7: What this role owns in TMA3084 | C7: M1 | D7: M2 | E7: M3 | F7: M4
A8: Team Leader | B8: Runs the launch and the weekly meeting, keeps the team to its plan, owns the relationship with the instructor and demonstrator, reports status. | C8: Aisyah Binti Rahman | D8: Aisyah Binti Rahman | E8: Daniel Wong Jun Hao | F8: Mei Ling Chong
A9: Product Owner | B9: Owns the client relationship and the backlog. Books and chairs client meetings, turns client needs into prioritised user stories, obtains sign-off. | C9: Harith Bin Ismail | D9: Harith Bin Ismail | E9: Priya Nair | F9: Aisyah Binti Rahman
A10: Development Manager | B10: Owns the Flutter codebase and the architecture. Allocates implementation work, enforces the branching model and the pull-request review rule. | C10: Daniel Wong Jun Hao | D10: Daniel Wong Jun Hao | E10: Harith Bin Ismail | F10: Priya Nair
A11: Planning Manager | B11: Owns TASK and SCHEDULE. Produces the plan, tracks earned value weekly, raises the alarm when the team drifts off plan. | C11: Mei Ling Chong | D11: Mei Ling Chong | E11: Aisyah Binti Rahman | F11: Harith Bin Ismail
A12: Quality & Test Manager | B12: Owns SUMQ, LOGD and LOGTEST - the review, inspection and test discipline. Tracks defect density, yield and coverage, chairs inspections, owns the AI-code review rule, and reports release readiness. | C12: Priya Nair | D12: Priya Nair | E12: Mei Ling Chong | F12: Daniel Wong Jun Hao
A13: Support Manager | B13: Owns the repository, CI/CD, environments, builds and configuration control. Maintains LOGGIT and the CCR log. | C13: Aisyah Binti Rahman | D13: Mei Ling Chong | E13: Daniel Wong Jun Hao | F13: Priya Nair
A15: Role Load Check - calculated from the matrix above, do not type here
A16: Member | B16: Reading | C16: M1 | D16: M2 | E16: M3 | F16: M4
A17: =IF('FORM-SI'!$C$9="","",'FORM-SI'!$C$9) | B17: =IF($A17="","",IF(MAX($C17:$F17)>2,"Holds more than two roles in a cycle",IF(MIN($C17:$F17)=0,"Has no role in at least one cycle",IF(MAX($C17:$F17)=2,"Doubles up in at least one cycle","One role in every cycle")))) | C17: =IF($A17="","",COUNTIF(C$8:C$13,$A17)) | D17: =IF($A17="","",COUNTIF(D$8:D$13,$A17)) | E17: =IF($A17="","",COUNTIF(E$8:E$13,$A17)) | F17: =IF($A17="","",COUNTIF(F$8:F$13,$A17))
A18: =IF('FORM-SI'!$C$10="","",'FORM-SI'!$C$10) | B18: =IF($A18="","",IF(MAX($C18:$F18)>2,"Holds more than two roles in a cycle",IF(MIN($C18:$F18)=0,"Has no role in at least one cycle",IF(MAX($C18:$F18)=2,"Doubles up in at least one cycle","One role in every cycle")))) | C18: =IF($A18="","",COUNTIF(C$8:C$13,$A18)) | D18: =IF($A18="","",COUNTIF(D$8:D$13,$A18)) | E18: =IF($A18="","",COUNTIF(E$8:E$13,$A18)) | F18: =IF($A18="","",COUNTIF(F$8:F$13,$A18))
A19: =IF('FORM-SI'!$C$11="","",'FORM-SI'!$C$11) | B19: =IF($A19="","",IF(MAX($C19:$F19)>2,"Holds more than two roles in a cycle",IF(MIN($C19:$F19)=0,"Has no role in at least one cycle",IF(MAX($C19:$F19)=2,"Doubles up in at least one cycle","One role in every cycle")))) | C19: =IF($A19="","",COUNTIF(C$8:C$13,$A19)) | D19: =IF($A19="","",COUNTIF(D$8:D$13,$A19)) | E19: =IF($A19="","",COUNTIF(E$8:E$13,$A19)) | F19: =IF($A19="","",COUNTIF(F$8:F$13,$A19))
A20: =IF('FORM-SI'!$C$12="","",'FORM-SI'!$C$12) | B20: =IF($A20="","",IF(MAX($C20:$F20)>2,"Holds more than two roles in a cycle",IF(MIN($C20:$F20)=0,"Has no role in at least one cycle",IF(MAX($C20:$F20)=2,"Doubles up in at least one cycle","One role in every cycle")))) | C20: =IF($A20="","",COUNTIF(C$8:C$13,$A20)) | D20: =IF($A20="","",COUNTIF(D$8:D$13,$A20)) | E20: =IF($A20="","",COUNTIF(E$8:E$13,$A20)) | F20: =IF($A20="","",COUNTIF(F$8:F$13,$A20))
A21: =IF('FORM-SI'!$C$13="","",'FORM-SI'!$C$13) | B21: =IF($A21="","",IF(MAX($C21:$F21)>2,"Holds more than two roles in a cycle",IF(MIN($C21:$F21)=0,"Has no role in at least one cycle",IF(MAX($C21:$F21)=2,"Doubles up in at least one cycle","One role in every cycle")))) | C21: =IF($A21="","",COUNTIF(C$8:C$13,$A21)) | D21: =IF($A21="","",COUNTIF(D$8:D$13,$A21)) | E21: =IF($A21="","",COUNTIF(E$8:E$13,$A21)) | F21: =IF($A21="","",COUNTIF(F$8:F$13,$A21))
A22: =IF('FORM-SI'!$C$14="","",'FORM-SI'!$C$14) | B22: =IF($A22="","",IF(MAX($C22:$F22)>2,"Holds more than two roles in a cycle",IF(MIN($C22:$F22)=0,"Has no role in at least one cycle",IF(MAX($C22:$F22)=2,"Doubles up in at least one cycle","One role in every cycle")))) | C22: =IF($A22="","",COUNTIF(C$8:C$13,$A22)) | D22: =IF($A22="","",COUNTIF(D$8:D$13,$A22)) | E22: =IF($A22="","",COUNTIF(E$8:E$13,$A22)) | F22: =IF($A22="","",COUNTIF(F$8:F$13,$A22))
A23: Members holding two roles | B23: =IF(SETUP!$C$16="","","Should be "&MAX(0,6-SETUP!$C$16)&" with a team of "&SETUP!$C$16) | C23: =COUNTIF(C$17:C$22,2) | D23: =COUNTIF(D$17:D$22,2) | E23: =COUNTIF(E$17:E$22,2) | F23: =COUNTIF(F$17:F$22,2)
A24: Roles filled | B24: ="All 6 roles must be held in every cycle" | C24: =COUNTA(C$8:C$13) | D24: =COUNTA(D$8:D$13) | E24: =COUNTA(E$8:E$13) | F24: =COUNTA(F$8:F$13)
A26: Role Rotation Rule
A27: There are six roles and five of you, so in every cycle exactly one member holds two roles and nobody holds more than two. The double role rotates - the same member does not carry it twice in a row - and every member holds a role in every cycle. No member may hold the same role for more than two consecutive milestones. Agree the rotation at the launch meeting and record it above; a change mid-cycle goes through the CCR log with the reason stated. If your team has four members, two of you will double up; the check above works that out from the team size.

Sheet GOALS
A1: Team & Role Goals
A2: A goal that cannot be measured is a wish. Every goal needs a number and an owner.
A4: Team | B4: =SETUP!$C$10
A6: Goals
A7: # | B7: Stakeholder | C7: Goal | D7: Measure | E7: Target | F7: Actual | G7: Owner | H7: Review By
A8: 1 | B8: Client | C8: SeaFresh accepts the app and uses it for real orders | D8: Client sign-off form signed | E8: Yes by M4 | F8: Yes | G8: Harith Bin Ismail | H8: 46389
A9: 2 | B9: Client | C9: Counter staff can place an order without training | D9: Time to first successful order, new user | E9: < 3 minutes | F9: 2 min 40 s | G9: Harith Bin Ismail | H9: 46374
A10: 3 | B10: Team | C10: Finish inside the planned effort | D10: Actual hours / planned hours | E10: 0.9 - 1.1 | F10: 0.75 | G10: Mei Ling Chong | H10: 46374
A11: 4 | B11: Team | C11: Work is shared evenly across the five of us | D11: Each member's share of logged hours | E11: within +/-40% of even | F11: not met - see DASHBOARD | G11: Aisyah Binti Rahman | H11: 46344
A12: 5 | B12: Quality | C12: Catch defects before they reach test | D12: % of defects removed before unit test | E12: >= 70% | F12: 73% | G12: Priya Nair | H12: 46374
A13: 6 | B13: Quality | C13: Nothing critical reaches the client | D13: Critical defects found in acceptance test | E13: 0 | F13: 0 | G13: Priya Nair | H13: 46389
A14: 7 | B14: Process | C14: Every AI-generated change is reviewed by someone else | D14: LOGAI rows approved / total rows | E14: 100% | F14: 100% | G14: Priya Nair | H14: 46374
A15: 8 | B15: Process | C15: develop stays releasable | D15: GitHub Actions pass rate on develop | E15: >= 95% | F15: 96% | G15: Aisyah Binti Rahman | H15: 46374
A16: 9
A17: 10
A18: 11
A19: 12
A20: 13
A21: 14
A23: Suggested starting goals (replace with your own)
B24: Stakeholder | C24: Goal | D24: Measure | E24: Target
B25: Client | C25: Client accepts the delivered app | D25: Client sign-off obtained | E25: Yes by M4
B26: Team | C26: Finish within the planned effort | D26: Actual hours / planned hours | E26: 0.9 - 1.1
B27: Quality | C27: Catch defects before test | D27: % defects removed before unit test | E27: >= 70%
B28: Quality | C28: Keep the released build clean | D28: Defects found in acceptance test | E28: 0 critical
B29: Process | C29: Every AI-generated change is reviewed | D29: LOGAI entries approved / total | E29: 100%
B30: Process | C30: Keep the main branch releasable | D30: GitHub Actions pass rate on develop | E30: >= 95%
B31: Individual | C31: Contribution is evenly shared | D31: Each member's share of team hours | E31: within +/-40% of even

Sheet STRAT
A1: Development Strategy
A2: What gets built in each cycle, what is reused, and what could go wrong.
A4: Cycle Strategy
A5: # | B5: Milestone | C5: Scope delivered this cycle | D5: Build / buy / reuse decision | E5: Main technical risk | F5: Mitigation | G5: Owner
A6: 1 | B6: M1 | C6: Requirements and a clickable prototype of the order screen. No real data yet. | D6: Build the app; reuse Firebase Auth rather than writing sign-in. | E6: The client has never used a tracking app and may not recognise what we design. | F6: Show paper mock-ups at the second client meeting before writing any code. | G6: Harith Bin Ismail
A7: 2 | B7: M2 | C7: Order entry, catalogue browsing and the local database. Prototype against seeded data. | D7: Build order entry; reuse an off-the-shelf PDF package for invoices. | E7: Supplier price list changes weekly and we had assumed it was static. | F7: Model prices as dated records from the start; agreed with client at meeting 3. | G7: Daniel Wong Jun Hao
A8: 3 | B8: M3 | C8: Live catalogue sync, invoice generation, full test suite and CI. | D8: Build sync; reuse Firestore offline persistence rather than our own cache. | E8: The shop's connection drops; orders could be lost mid-entry. | F8: Offline-first write queue plus an integration test that simulates loss of connection. | G8: Harith Bin Ismail
A9: 4 | B9: M4 | C9: Release build, user manual, demo video and handover to the client. | D9: No new build; packaging and documentation only. | E9: Counter staff may not adopt it after handover. | F9: Train two staff in person at handover and leave a one-page card at the till. | G9: Aisyah Binti Rahman
A11: Technology Stack Decisions
A12: # | B12: Area | C12: Decision | D12: Why | E12: Alternative considered | F12: Decided | G12: Owner
A13: 1 | B13: Mobile framework | C13: Flutter 3.x / Dart 3 | D13: One codebase for Android and iOS; the course requires it. | E13: Native Kotlin - rejected, no iOS and no time for two codebases. | F13: 46303 | G13: Daniel Wong Jun Hao
A14: 2 | B14: State management | C14: Riverpod | D14: Compile-safe, testable, and easier to reason about than InheritedWidget. | E14: Provider - simpler but we wanted the compile-time safety. | F14: 46303 | G14: Daniel Wong Jun Hao
A15: 3 | B15: Backend / data | C15: Firebase Firestore + offline persistence | D15: The shop's connection is unreliable; offline-first is the whole point. | E15: Supabase - good, but we already had Firebase Auth. | F15: 46310 | G15: Harith Bin Ismail
A16: 4 | B16: AI capability & API | C16: Gemini API for the order-note parser | D16: Lets staff type 'two boxes tiger prawn' instead of browsing the catalogue. | E16: Rule-based parser - brittle against the way staff actually write. | F16: 46317 | G16: Priya Nair
A17: 5 | B17: Authentication | C17: Firebase Auth (email + phone) | D17: Staff share a counter device; phone sign-in is the simplest for them. | E17: Custom JWT - more work, no benefit here. | F17: 46310 | G17: Aisyah Binti Rahman
A18: 6 | B18: Testing framework | C18: flutter_test + mockito + integration_test | D18: Standard toolchain, works in CI without extra setup. | E18: None seriously considered. | F18: 46324 | G18: Mei Ling Chong
A19: 7 | B19: CI/CD | C19: GitHub Actions | D19: Free for the repo, runs analyze + test + coverage on every PR. | E19: Codemagic - nicer mobile builds, but needed a paid tier for our frequency. | F19: 46324 | G19: Aisyah Binti Rahman
A20: 8 | B20: Release channel | C20: Internal APK via GitHub Releases | D20: The client has two Android devices; no store listing needed for the pilot. | E20: Play Store internal testing - rejected, review delay would hit M4. | F20: 46366 | G20: Aisyah Binti Rahman

Sheet TASK
A1: Form TASK - Task Plan & Earned Value
A2: Break the cycle into tasks of roughly 2-10 hours. A task is done or it is not - no part marks.
A4: Team | B4: =SETUP!$C$10 | E4: Tasks | F4: =COUNTA(TASK!$A$8:$A$127) | G4: Plan hrs | H4: =SUM(TASK!$K$8:$K$127) | I4: Actual hrs | J4: =SUM(TASK!$M$8:$M$127) | L4: Complete | N4: =COUNTIF(TASK!$O$8:$O$127,"Complete") | O4: Earned value | Q4: =SUM(TASK!$Q$8:$Q$127)
A7: Task ID | B7: M/stone | C7: Phase | D7: Component | E7: Task | F7: Owner | G7: Est. size | H7: Size measure | I7: Rate /hr | J7: Est. hrs | K7: Plan hrs | L7: Plan wk | M7: Actual hrs | N7: Act. wk | O7: Status | P7: Plan value | Q7: Earned value | R7: Cum PV | S7: Cum EV
A8: T01 | B8: M1 | C8: MGMT | D8: SYSTEM | E8: Team admin, lab attendance, instructor check-ins | F8: Aisyah Binti Rahman | J8: =IF(OR(N($G8)=0,N($I8)=0),"",$G8/$I8) | K8: 7 | L8: 3 | M8: =IF($A8="","",SUMIFS(LOGT!$K$7:$K$406,LOGT!$F$7:$F$406,$A8)/60) | N8: =IFERROR(IF(N($M8)=0,"",3+INT((SUMPRODUCT(MAX((LOGT!$F$7:$F$406=$A8)*LOGT!$A$7:$A$406))-DATE(2026,10,5))/7)),"") | O8: Complete | P8: =IF(OR($A8="",SUM(TASK!$K$8:$K$127)=0),"",$K8/SUM(TASK!$K$8:$K$127)) | Q8: =IF($A8="","",IF($O8="Complete",$P8,0)) | R8: =IF($A8="","",SUM($P$8:$P8)) | S8: =IF($A8="","",SUM($Q$8:$Q8))
A9: T02 | B9: M1 | C9: STRAT | D9: SYSTEM | E9: Launch meeting, cycle strategy and stack decisions | F9: Aisyah Binti Rahman | J9: =IF(OR(N($G9)=0,N($I9)=0),"",$G9/$I9) | K9: 11 | L9: 3 | M9: =IF($A9="","",SUMIFS(LOGT!$K$7:$K$406,LOGT!$F$7:$F$406,$A9)/60) | N9: =IFERROR(IF(N($M9)=0,"",3+INT((SUMPRODUCT(MAX((LOGT!$F$7:$F$406=$A9)*LOGT!$A$7:$A$406))-DATE(2026,10,5))/7)),"") | O9: Complete | P9: =IF(OR($A9="",SUM(TASK!$K$8:$K$127)=0),"",$K9/SUM(TASK!$K$8:$K$127)) | Q9: =IF($A9="","",IF($O9="Complete",$P9,0)) | R9: =IF($A9="","",SUM($P$8:$P9)) | S9: =IF($A9="","",SUM($Q$8:$Q9))
A10: T03 | B10: M1 | C10: PLAN | D10: SYSTEM | E10: Task and schedule plan for the cycle | F10: Mei Ling Chong | J10: =IF(OR(N($G10)=0,N($I10)=0),"",$G10/$I10) | K10: 10.5 | L10: 3 | M10: =IF($A10="","",SUMIFS(LOGT!$K$7:$K$406,LOGT!$F$7:$F$406,$A10)/60) | N10: =IFERROR(IF(N($M10)=0,"",3+INT((SUMPRODUCT(MAX((LOGT!$F$7:$F$406=$A10)*LOGT!$A$7:$A$406))-DATE(2026,10,5))/7)),"") | O10: Complete | P10: =IF(OR($A10="",SUM(TASK!$K$8:$K$127)=0),"",$K10/SUM(TASK!$K$8:$K$127)) | Q10: =IF($A10="","",IF($O10="Complete",$P10,0)) | R10: =IF($A10="","",SUM($P$8:$P10)) | S10: =IF($A10="","",SUM($Q$8:$Q10))
A11: T04 | B11: M1 | C11: REQ | D11: SYSTEM | E11: Elicit requirements from SeaFresh and write the SRS | F11: Harith Bin Ismail | J11: =IF(OR(N($G11)=0,N($I11)=0),"",$G11/$I11) | K11: 7 | L11: 4 | M11: =IF($A11="","",SUMIFS(LOGT!$K$7:$K$406,LOGT!$F$7:$F$406,$A11)/60) | N11: =IFERROR(IF(N($M11)=0,"",3+INT((SUMPRODUCT(MAX((LOGT!$F$7:$F$406=$A11)*LOGT!$A$7:$A$406))-DATE(2026,10,5))/7)),"") | O11: Complete | P11: =IF(OR($A11="",SUM(TASK!$K$8:$K$127)=0),"",$K11/SUM(TASK!$K$8:$K$127)) | Q11: =IF($A11="","",IF($O11="Complete",$P11,0)) | R11: =IF($A11="","",SUM($P$8:$P11)) | S11: =IF($A11="","",SUM($Q$8:$Q11))
A12: T05 | B12: M1 | C12: STP | D12: SYSTEM | E12: System test plan | F12: Mei Ling Chong | J12: =IF(OR(N($G12)=0,N($I12)=0),"",$G12/$I12) | K12: 6 | L12: 4 | M12: =IF($A12="","",SUMIFS(LOGT!$K$7:$K$406,LOGT!$F$7:$F$406,$A12)/60) | N12: =IFERROR(IF(N($M12)=0,"",3+INT((SUMPRODUCT(MAX((LOGT!$F$7:$F$406=$A12)*LOGT!$A$7:$A$406))-DATE(2026,10,5))/7)),"") | O12: Complete | P12: =IF(OR($A12="",SUM(TASK!$K$8:$K$127)=0),"",$K12/SUM(TASK!$K$8:$K$127)) | Q12: =IF($A12="","",IF($O12="Complete",$P12,0)) | R12: =IF($A12="","",SUM($P$8:$P12)) | S12: =IF($A12="","",SUM($Q$8:$Q12))
A13: T06 | B13: M1 | C13: REQINSP | D13: SYSTEM | E13: Team inspection of the SRS | F13: Harith Bin Ismail | J13: =IF(OR(N($G13)=0,N($I13)=0),"",$G13/$I13) | K13: 11 | L13: 4 | M13: =IF($A13="","",SUMIFS(LOGT!$K$7:$K$406,LOGT!$F$7:$F$406,$A13)/60) | N13: =IFERROR(IF(N($M13)=0,"",3+INT((SUMPRODUCT(MAX((LOGT!$F$7:$F$406=$A13)*LOGT!$A$7:$A$406))-DATE(2026,10,5))/7)),"") | O13: Complete | P13: =IF(OR($A13="",SUM(TASK!$K$8:$K$127)=0),"",$K13/SUM(TASK!$K$8:$K$127)) | Q13: =IF($A13="","",IF($O13="Complete",$P13,0)) | R13: =IF($A13="","",SUM($P$8:$P13)) | S13: =IF($A13="","",SUM($Q$8:$Q13))
A14: T07 | B14: M1 | C14: HLD | D14: SYSTEM | E14: Architecture and SDD | F14: Daniel Wong Jun Hao | J14: =IF(OR(N($G14)=0,N($I14)=0),"",$G14/$I14) | K14: 9.5 | L14: 4 | M14: =IF($A14="","",SUMIFS(LOGT!$K$7:$K$406,LOGT!$F$7:$F$406,$A14)/60) | N14: =IFERROR(IF(N($M14)=0,"",3+INT((SUMPRODUCT(MAX((LOGT!$F$7:$F$406=$A14)*LOGT!$A$7:$A$406))-DATE(2026,10,5))/7)),"") | O14: Complete | P14: =IF(OR($A14="",SUM(TASK!$K$8:$K$127)=0),"",$K14/SUM(TASK!$K$8:$K$127)) | Q14: =IF($A14="","",IF($O14="Complete",$P14,0)) | R14: =IF($A14="","",SUM($P$8:$P14)) | S14: =IF($A14="","",SUM($Q$8:$Q14))
A15: T08 | B15: M1 | C15: ITP | D15: SYSTEM | E15: Integration test plan | F15: Mei Ling Chong | J15: =IF(OR(N($G15)=0,N($I15)=0),"",$G15/$I15) | K15: 6 | L15: 4 | M15: =IF($A15="","",SUMIFS(LOGT!$K$7:$K$406,LOGT!$F$7:$F$406,$A15)/60) | N15: =IFERROR(IF(N($M15)=0,"",3+INT((SUMPRODUCT(MAX((LOGT!$F$7:$F$406=$A15)*LOGT!$A$7:$A$406))-DATE(2026,10,5))/7)),"") | O15: Complete | P15: =IF(OR($A15="",SUM(TASK!$K$8:$K$127)=0),"",$K15/SUM(TASK!$K$8:$K$127)) | Q15: =IF($A15="","",IF($O15="Complete",$P15,0)) | R15: =IF($A15="","",SUM($P$8:$P15)) | S15: =IF($A15="","",SUM($Q$8:$Q15))
A16: T09 | B16: M1 | C16: HLDINSP | D16: SYSTEM | E16: Team inspection of the SDD | F16: Daniel Wong Jun Hao | J16: =IF(OR(N($G16)=0,N($I16)=0),"",$G16/$I16) | K16: 6 | L16: 4 | M16: =IF($A16="","",SUMIFS(LOGT!$K$7:$K$406,LOGT!$F$7:$F$406,$A16)/60) | N16: =IFERROR(IF(N($M16)=0,"",3+INT((SUMPRODUCT(MAX((LOGT!$F$7:$F$406=$A16)*LOGT!$A$7:$A$406))-DATE(2026,10,5))/7)),"") | O16: Complete | P16: =IF(OR($A16="",SUM(TASK!$K$8:$K$127)=0),"",$K16/SUM(TASK!$K$8:$K$127)) | Q16: =IF($A16="","",IF($O16="Complete",$P16,0)) | R16: =IF($A16="","",SUM($P$8:$P16)) | S16: =IF($A16="","",SUM($Q$8:$Q16))
A17: T10 | B17: M1 | C17: DLD | D17: UI / screens | E17: Detailed design of screens, widgets and models | F17: Priya Nair | J17: =IF(OR(N($G17)=0,N($I17)=0),"",$G17/$I17) | K17: 10.5 | L17: 5 | M17: =IF($A17="","",SUMIFS(LOGT!$K$7:$K$406,LOGT!$F$7:$F$406,$A17)/60) | N17: =IFERROR(IF(N($M17)=0,"",3+INT((SUMPRODUCT(MAX((LOGT!$F$7:$F$406=$A17)*LOGT!$A$7:$A$406))-DATE(2026,10,5))/7)),"") | O17: Complete | P17: =IF(OR($A17="",SUM(TASK!$K$8:$K$127)=0),"",$K17/SUM(TASK!$K$8:$K$127)) | Q17: =IF($A17="","",IF($O17="Complete",$P17,0)) | R17: =IF($A17="","",SUM($P$8:$P17)) | S17: =IF($A17="","",SUM($Q$8:$Q17))
A18: T11 | B18: M1 | C18: DLDR | D18: UI / screens | E18: Personal review of the detailed design | F18: Priya Nair | J18: =IF(OR(N($G18)=0,N($I18)=0),"",$G18/$I18) | K18: 12.5 | L18: 5 | M18: =IF($A18="","",SUMIFS(LOGT!$K$7:$K$406,LOGT!$F$7:$F$406,$A18)/60) | N18: =IFERROR(IF(N($M18)=0,"",3+INT((SUMPRODUCT(MAX((LOGT!$F$7:$F$406=$A18)*LOGT!$A$7:$A$406))-DATE(2026,10,5))/7)),"") | O18: Complete | P18: =IF(OR($A18="",SUM(TASK!$K$8:$K$127)=0),"",$K18/SUM(TASK!$K$8:$K$127)) | Q18: =IF($A18="","",IF($O18="Complete",$P18,0)) | R18: =IF($A18="","",SUM($P$8:$P18)) | S18: =IF($A18="","",SUM($Q$8:$Q18))
A19: T12 | B19: M1 | C19: TD | D19: UI / screens | E19: Write the test cases for this component | F19: Priya Nair | J19: =IF(OR(N($G19)=0,N($I19)=0),"",$G19/$I19) | K19: 17 | L19: 5 | M19: =IF($A19="","",SUMIFS(LOGT!$K$7:$K$406,LOGT!$F$7:$F$406,$A19)/60) | N19: =IFERROR(IF(N($M19)=0,"",3+INT((SUMPRODUCT(MAX((LOGT!$F$7:$F$406=$A19)*LOGT!$A$7:$A$406))-DATE(2026,10,5))/7)),"") | O19: Complete | P19: =IF(OR($A19="",SUM(TASK!$K$8:$K$127)=0),"",$K19/SUM(TASK!$K$8:$K$127)) | Q19: =IF($A19="","",IF($O19="Complete",$P19,0)) | R19: =IF($A19="","",SUM($P$8:$P19)) | S19: =IF($A19="","",SUM($Q$8:$Q19))
... A53: T46 | B53: M3 | C53: AIGEN | D53: Local store & sync | E53: Generate the offline write-queue scaffolding | F53: Mei Ling Chong | J53: =IF(OR(N($G53)=0,N($I53)=0),"",$G53/$I53) | K53: 8 | L53: 10 | M53: =IF($A53="","",SUMIFS(LOGT!$K$7:$K$406,LOGT!$F$7:$F$406,$A53)/60) | N53: =IFERROR(IF(N($M53)=0,"",3+INT((SUMPRODUCT(MAX((LOGT!$F$7:$F$406=$A53)*LOGT!$A$7:$A$406))-DATE(2026,10,5))/7)),"") | O53: Complete | P53: =IF(OR($A53="",SUM(TASK!$K$8:$K$127)=0),"",$K53/SUM(TASK!$K$8:$K$127)) | Q53: =IF($A53="","",IF($O53="Complete",$P53,0)) | R53: =IF($A53="","",SUM($P$8:$P53)) | S53: =IF($A53="","",SUM($Q$8:$Q53))
J54: =IF(OR(N($G54)=0,N($I54)=0),"",$G54/$I54) | M54: =IF($A54="","",SUMIFS(LOGT!$K$7:$K$406,LOGT!$F$7:$F$406,$A54)/60) | N54: =IFERROR(IF(N($M54)=0,"",3+INT((SUMPRODUCT(MAX((LOGT!$F$7:$F$406=$A54)*LOGT!$A$7:$A$406))-DATE(2026,10,5))/7)),"") | P54: =IF(OR($A54="",SUM(TASK!$K$8:$K$127)=0),"",$K54/SUM(TASK!$K$8:$K$127)) | Q54: =IF($A54="","",IF($O54="Complete",$P54,0)) | R54: =IF($A54="","",SUM($P$8:$P54)) | S54: =IF($A54="","",SUM($Q$8:$Q54))
J55: =IF(OR(N($G55)=0,N($I55)=0),"",$G55/$I55) | M55: =IF($A55="","",SUMIFS(LOGT!$K$7:$K$406,LOGT!$F$7:$F$406,$A55)/60) | N55: =IFERROR(IF(N($M55)=0,"",3+INT((SUMPRODUCT(MAX((LOGT!$F$7:$F$406=$A55)*LOGT!$A$7:$A$406))-DATE(2026,10,5))/7)),"") | P55: =IF(OR($A55="",SUM(TASK!$K$8:$K$127)=0),"",$K55/SUM(TASK!$K$8:$K$127)) | Q55: =IF($A55="","",IF($O55="Complete",$P55,0)) | R55: =IF($A55="","",SUM($P$8:$P55)) | S55: =IF($A55="","",SUM($Q$8:$Q55))
J56: =IF(OR(N($G56)=0,N($I56)=0),"",$G56/$I56) | M56: =IF($A56="","",SUMIFS(LOGT!$K$7:$K$406,LOGT!$F$7:$F$406,$A56)/60) | N56: =IFERROR(IF(N($M56)=0,"",3+INT((SUMPRODUCT(MAX((LOGT!$F$7:$F$406=$A56)*LOGT!$A$7:$A$406))-DATE(2026,10,5))/7)),"") | P56: =IF(OR($A56="",SUM(TASK!$K$8:$K$127)=0),"",$K56/SUM(TASK!$K$8:$K$127)) | Q56: =IF($A56="","",IF($O56="Complete",$P56,0)) | R56: =IF($A56="","",SUM($P$8:$P56)) | S56: =IF($A56="","",SUM($Q$8:$Q56))
J57: =IF(OR(N($G57)=0,N($I57)=0),"",$G57/$I57) | M57: =IF($A57="","",SUMIFS(LOGT!$K$7:$K$406,LOGT!$F$7:$F$406,$A57)/60) | N57: =IFERROR(IF(N($M57)=0,"",3+INT((SUMPRODUCT(MAX((LOGT!$F$7:$F$406=$A57)*LOGT!$A$7:$A$406))-DATE(2026,10,5))/7)),"") | P57: =IF(OR($A57="",SUM(TASK!$K$8:$K$127)=0),"",$K57/SUM(TASK!$K$8:$K$127)) | Q57: =IF($A57="","",IF($O57="Complete",$P57,0)) | R57: =IF($A57="","",SUM($P$8:$P57)) | S57: =IF($A57="","",SUM($Q$8:$Q57))
J58: =IF(OR(N($G58)=0,N($I58)=0),"",$G58/$I58) | M58: =IF($A58="","",SUMIFS(LOGT!$K$7:$K$406,LOGT!$F$7:$F$406,$A58)/60) | N58: =IFERROR(IF(N($M58)=0,"",3+INT((SUMPRODUCT(MAX((LOGT!$F$7:$F$406=$A58)*LOGT!$A$7:$A$406))-DATE(2026,10,5))/7)),"") | P58: =IF(OR($A58="",SUM(TASK!$K$8:$K$127)=0),"",$K58/SUM(TASK!$K$8:$K$127)) | Q58: =IF($A58="","",IF($O58="Complete",$P58,0)) | R58: =IF($A58="","",SUM($P$8:$P58)) | S58: =IF($A58="","",SUM($Q$8:$Q58))
J59: =IF(OR(N($G59)=0,N($I59)=0),"",$G59/$I59) | M59: =IF($A59="","",SUMIFS(LOGT!$K$7:$K$406,LOGT!$F$7:$F$406,$A59)/60) | N59: =IFERROR(IF(N($M59)=0,"",3+INT((SUMPRODUCT(MAX((LOGT!$F$7:$F$406=$A59)*LOGT!$A$7:$A$406))-DATE(2026,10,5))/7)),"") | P59: =IF(OR($A59="",SUM(TASK!$K$8:$K$127)=0),"",$K59/SUM(TASK!$K$8:$K$127)) | Q59: =IF($A59="","",IF($O59="Complete",$P59,0)) | R59: =IF($A59="","",SUM($P$8:$P59)) | S59: =IF($A59="","",SUM($Q$8:$Q59))
J60: =IF(OR(N($G60)=0,N($I60)=0),"",$G60/$I60) | M60: =IF($A60="","",SUMIFS(LOGT!$K$7:$K$406,LOGT!$F$7:$F$406,$A60)/60) | N60: =IFERROR(IF(N($M60)=0,"",3+INT((SUMPRODUCT(MAX((LOGT!$F$7:$F$406=$A60)*LOGT!$A$7:$A$406))-DATE(2026,10,5))/7)),"") | P60: =IF(OR($A60="",SUM(TASK!$K$8:$K$127)=0),"",$K60/SUM(TASK!$K$8:$K$127)) | Q60: =IF($A60="","",IF($O60="Complete",$P60,0)) | R60: =IF($A60="","",SUM($P$8:$P60)) | S60: =IF($A60="","",SUM($Q$8:$Q60))
J61: =IF(OR(N($G61)=0,N($I61)=0),"",$G61/$I61) | M61: =IF($A61="","",SUMIFS(LOGT!$K$7:$K$406,LOGT!$F$7:$F$406,$A61)/60) | N61: =IFERROR(IF(N($M61)=0,"",3+INT((SUMPRODUCT(MAX((LOGT!$F$7:$F$406=$A61)*LOGT!$A$7:$A$406))-DATE(2026,10,5))/7)),"") | P61: =IF(OR($A61="",SUM(TASK!$K$8:$K$127)=0),"",$K61/SUM(TASK!$K$8:$K$127)) | Q61: =IF($A61="","",IF($O61="Complete",$P61,0)) | R61: =IF($A61="","",SUM($P$8:$P61)) | S61: =IF($A61="","",SUM($Q$8:$Q61))
J62: =IF(OR(N($G62)=0,N($I62)=0),"",$G62/$I62) | M62: =IF($A62="","",SUMIFS(LOGT!$K$7:$K$406,LOGT!$F$7:$F$406,$A62)/60) | N62: =IFERROR(IF(N($M62)=0,"",3+INT((SUMPRODUCT(MAX((LOGT!$F$7:$F$406=$A62)*LOGT!$A$7:$A$406))-DATE(2026,10,5))/7)),"") | P62: =IF(OR($A62="",SUM(TASK!$K$8:$K$127)=0),"",$K62/SUM(TASK!$K$8:$K$127)) | Q62: =IF($A62="","",IF($O62="Complete",$P62,0)) | R62: =IF($A62="","",SUM($P$8:$P62)) | S62: =IF($A62="","",SUM($Q$8:$Q62))
J63: =IF(OR(N($G63)=0,N($I63)=0),"",$G63/$I63) | M63: =IF($A63="","",SUMIFS(LOGT!$K$7:$K$406,LOGT!$F$7:$F$406,$A63)/60) | N63: =IFERROR(IF(N($M63)=0,"",3+INT((SUMPRODUCT(MAX((LOGT!$F$7:$F$406=$A63)*LOGT!$A$7:$A$406))-DATE(2026,10,5))/7)),"") | P63: =IF(OR($A63="",SUM(TASK!$K$8:$K$127)=0),"",$K63/SUM(TASK!$K$8:$K$127)) | Q63: =IF($A63="","",IF($O63="Complete",$P63,0)) | R63: =IF($A63="","",SUM($P$8:$P63)) | S63: =IF($A63="","",SUM($Q$8:$Q63))
J64: =IF(OR(N($G64)=0,N($I64)=0),"",$G64/$I64) | M64: =IF($A64="","",SUMIFS(LOGT!$K$7:$K$406,LOGT!$F$7:$F$406,$A64)/60) | N64: =IFERROR(IF(N($M64)=0,"",3+INT((SUMPRODUCT(MAX((LOGT!$F$7:$F$406=$A64)*LOGT!$A$7:$A$406))-DATE(2026,10,5))/7)),"") | P64: =IF(OR($A64="",SUM(TASK!$K$8:$K$127)=0),"",$K64/SUM(TASK!$K$8:$K$127)) | Q64: =IF($A64="","",IF($O64="Complete",$P64,0)) | R64: =IF($A64="","",SUM($P$8:$P64)) | S64: =IF($A64="","",SUM($Q$8:$Q64))
J65: =IF(OR(N($G65)=0,N($I65)=0),"",$G65/$I65) | M65: =IF($A65="","",SUMIFS(LOGT!$K$7:$K$406,LOGT!$F$7:$F$406,$A65)/60) | N65: =IFERROR(IF(N($M65)=0,"",3+INT((SUMPRODUCT(MAX((LOGT!$F$7:$F$406=$A65)*LOGT!$A$7:$A$406))-DATE(2026,10,5))/7)),"") | P65: =IF(OR($A65="",SUM(TASK!$K$8:$K$127)=0),"",$K65/SUM(TASK!$K$8:$K$127)) | Q65: =IF($A65="","",IF($O65="Complete",$P65,0)) | R65: =IF($A65="","",SUM($P$8:$P65)) | S65: =IF($A65="","",SUM($Q$8:$Q65))
... J127: =IF(OR(N($G127)=0,N($I127)=0),"",$G127/$I127) | M127: =IF($A127="","",SUMIFS(LOGT!$K$7:$K$406,LOGT!$F$7:$F$406,$A127)/60) | N127: =IFERROR(IF(N($M127)=0,"",3+INT((SUMPRODUCT(MAX((LOGT!$F$7:$F$406=$A127)*LOGT!$A$7:$A$406))-DATE(2026,10,5))/7)),"") | P127: =IF(OR($A127="",SUM(TASK!$K$8:$K$127)=0),"",$K127/SUM(TASK!$K$8:$K$127)) | Q127: =IF($A127="","",IF($O127="Complete",$P127,0)) | R127: =IF($A127="","",SUM($P$8:$P127)) | S127: =IF($A127="","",SUM($Q$8:$Q127))

Sheet SCHEDULE
A1: Form SCHEDULE - Weekly Schedule & Earned Value
A2: Planned hours are what the team commits to. Earned value is what it actually delivered.
A4: Team | B4: =SETUP!$C$10 | E4: Task plan hrs | F4: =SUM(TASK!$K$8:$K$127) | G4: Schedule plan hrs | H4: =SUM(C8:C20) | I4: Difference | J4: =H4-F4
A7: Week | B7: Week starting | C7: Plan hrs | D7: Cum plan | E7: Actual hrs | F7: Cum actual | G7: Plan value | H7: Cum PV | I7: Earned value | J7: Cum EV | K7: EV vs PV | L7: Comment
A8: 3 | B8: 46300 | C8: 28.5 | D8: =SUM($C$8:$C8) | E8: =SUMIFS(LOGT!$K$7:$K$406,LOGT!$D$7:$D$406,$A8)/60 | F8: =SUM($E$8:$E8) | G8: =SUMIFS(TASK!$P$8:$P$127,TASK!$L$8:$L$127,$A8) | H8: =SUM($G$8:$G8) | I8: =SUMIFS(TASK!$Q$8:$Q$127,TASK!$N$8:$N$127,$A8) | J8: =SUM($I$8:$I8) | K8: =$J8-$H8 | L8: Launch week - plan built here
A9: 4 | B9: 46307 | C9: 45.5 | D9: =SUM($C$8:$C9) | E9: =SUMIFS(LOGT!$K$7:$K$406,LOGT!$D$7:$D$406,$A9)/60 | F9: =SUM($E$8:$E9) | G9: =SUMIFS(TASK!$P$8:$P$127,TASK!$L$8:$L$127,$A9) | H9: =SUM($G$8:$G9) | I9: =SUMIFS(TASK!$Q$8:$Q$127,TASK!$N$8:$N$127,$A9) | J9: =SUM($I$8:$I9) | K9: =$J9-$H9
A10: 5 | B10: 46314 | C10: 51.5 | D10: =SUM($C$8:$C10) | E10: =SUMIFS(LOGT!$K$7:$K$406,LOGT!$D$7:$D$406,$A10)/60 | F10: =SUM($E$8:$E10) | G10: =SUMIFS(TASK!$P$8:$P$127,TASK!$L$8:$L$127,$A10) | H10: =SUM($G$8:$G10) | I10: =SUMIFS(TASK!$Q$8:$Q$127,TASK!$N$8:$N$127,$A10) | J10: =SUM($I$8:$I10) | K10: =$J10-$H10 | L10: M1 submitted
A11: 6 | B11: 46321 | C11: 60 | D11: =SUM($C$8:$C11) | E11: =SUMIFS(LOGT!$K$7:$K$406,LOGT!$D$7:$D$406,$A11)/60 | F11: =SUM($E$8:$E11) | G11: =SUMIFS(TASK!$P$8:$P$127,TASK!$L$8:$L$127,$A11) | H11: =SUM($G$8:$G11) | I11: =SUMIFS(TASK!$Q$8:$Q$127,TASK!$N$8:$N$127,$A11) | J11: =SUM($I$8:$I11) | K11: =$J11-$H11
A12: 7 | B12: 46328 | C12: 91 | D12: =SUM($C$8:$C12) | E12: =SUMIFS(LOGT!$K$7:$K$406,LOGT!$D$7:$D$406,$A12)/60 | F12: =SUM($E$8:$E12) | G12: =SUMIFS(TASK!$P$8:$P$127,TASK!$L$8:$L$127,$A12) | H12: =SUM($G$8:$G12) | I12: =SUMIFS(TASK!$Q$8:$Q$127,TASK!$N$8:$N$127,$A12) | J12: =SUM($I$8:$I12) | K12: =$J12-$H12
A13: 8 | B13: 46335 | C13: 0 | D13: =SUM($C$8:$C13) | E13: =SUMIFS(LOGT!$K$7:$K$406,LOGT!$D$7:$D$406,$A13)/60 | F13: =SUM($E$8:$E13) | G13: =SUMIFS(TASK!$P$8:$P$127,TASK!$L$8:$L$127,$A13) | H13: =SUM($G$8:$G13) | I13: =SUMIFS(TASK!$Q$8:$Q$127,TASK!$N$8:$N$127,$A13) | J13: =SUM($I$8:$I13) | K13: =$J13-$H13 | L13: Mid-semester break, no work planned
A14: 9 | B14: 46342 | C14: 93 | D14: =SUM($C$8:$C14) | E14: =SUMIFS(LOGT!$K$7:$K$406,LOGT!$D$7:$D$406,$A14)/60 | F14: =SUM($E$8:$E14) | G14: =SUMIFS(TASK!$P$8:$P$127,TASK!$L$8:$L$127,$A14) | H14: =SUM($G$8:$G14) | I14: =SUMIFS(TASK!$Q$8:$Q$127,TASK!$N$8:$N$127,$A14) | J14: =SUM($I$8:$I14) | K14: =$J14-$H14 | L14: M2 submitted
A15: 10 | B15: 46349 | C15: 76.5 | D15: =SUM($C$8:$C15) | E15: =SUMIFS(LOGT!$K$7:$K$406,LOGT!$D$7:$D$406,$A15)/60 | F15: =SUM($E$8:$E15) | G15: =SUMIFS(TASK!$P$8:$P$127,TASK!$L$8:$L$127,$A15) | H15: =SUM($G$8:$G15) | I15: =SUMIFS(TASK!$Q$8:$Q$127,TASK!$N$8:$N$127,$A15) | J15: =SUM($I$8:$I15) | K15: =$J15-$H15
A16: 11 | B16: 46356 | C16: 38 | D16: =SUM($C$8:$C16) | E16: =SUMIFS(LOGT!$K$7:$K$406,LOGT!$D$7:$D$406,$A16)/60 | F16: =SUM($E$8:$E16) | G16: =SUMIFS(TASK!$P$8:$P$127,TASK!$L$8:$L$127,$A16) | H16: =SUM($G$8:$G16) | I16: =SUMIFS(TASK!$Q$8:$Q$127,TASK!$N$8:$N$127,$A16) | J16: =SUM($I$8:$I16) | K16: =$J16-$H16
A17: 12 | B17: 46363 | C17: 56 | D17: =SUM($C$8:$C17) | E17: =SUMIFS(LOGT!$K$7:$K$406,LOGT!$D$7:$D$406,$A17)/60 | F17: =SUM($E$8:$E17) | G17: =SUMIFS(TASK!$P$8:$P$127,TASK!$L$8:$L$127,$A17) | H17: =SUM($G$8:$G17) | I17: =SUMIFS(TASK!$Q$8:$Q$127,TASK!$N$8:$N$127,$A17) | J17: =SUM($I$8:$I17) | K17: =$J17-$H17 | L17: System test and acceptance
A18: 13 | B18: 46370 | C18: 0 | D18: =SUM($C$8:$C18) | E18: =SUMIFS(LOGT!$K$7:$K$406,LOGT!$D$7:$D$406,$A18)/60 | F18: =SUM($E$8:$E18) | G18: =SUMIFS(TASK!$P$8:$P$127,TASK!$L$8:$L$127,$A18) | H18: =SUM($G$8:$G18) | I18: =SUMIFS(TASK!$Q$8:$Q$127,TASK!$N$8:$N$127,$A18) | J18: =SUM($I$8:$I18) | K18: =$J18-$H18 | L18: M3 submitted
A19: 14 | B19: 46377 | C19: 0 | D19: =SUM($C$8:$C19) | E19: =SUMIFS(LOGT!$K$7:$K$406,LOGT!$D$7:$D$406,$A19)/60 | F19: =SUM($E$8:$E19) | G19: =SUMIFS(TASK!$P$8:$P$127,TASK!$L$8:$L$127,$A19) | H19: =SUM($G$8:$G19) | I19: =SUMIFS(TASK!$Q$8:$Q$127,TASK!$N$8:$N$127,$A19) | J19: =SUM($I$8:$I19) | K19: =$J19-$H19
A20: 15 | B20: 46384 | C20: 0 | D20: =SUM($C$8:$C20) | E20: =SUMIFS(LOGT!$K$7:$K$406,LOGT!$D$7:$D$406,$A20)/60 | F20: =SUM($E$8:$E20) | G20: =SUMIFS(TASK!$P$8:$P$127,TASK!$L$8:$L$127,$A20) | H20: =SUM($G$8:$G20) | I20: =SUMIFS(TASK!$Q$8:$Q$127,TASK!$N$8:$N$127,$A20) | J20: =SUM($I$8:$I20) | K20: =$J20-$H20 | L20: M4 - presentation and handover
B21: TOTAL | C21: =SUM(C$8:C$20) | E21: =SUM(E$8:E$20)

Sheet LOGT
A1: Form LOGT - Time Recording Log
A2: One row per working session. Delta is calculated; never type over it.
A4: Team | B4: =SETUP!$C$10 | E4: Total hours logged | G4: =SUM(LOGT!$K$7:$K$406)/60 | H4: Sessions | I4: =COUNT(LOGT!$K$7:$K$406)
A6: Date | B6: Member | C6: Milestone | D6: Week | E6: Phase | F6: Task ID | G6: Component / what you worked on | H6: Start | I6: Stop | J6: Interrupt (min) | K6: Delta (min) | L6: AI used? | M6: Comments
A7: 46300 | B7: Aisyah Binti Rahman | C7: M1 | D7: =IF($A7="","",3+INT(($A7-DATE(2026,10,5))/7)) | E7: MGMT | F7: T01 | G7: SYSTEM - Team admin, lab attendance, instructor check-ins | H7: 0.41666667 | I7: 0.49722222 | J7: 0 | K7: =IF(OR($H7="",$I7=""),"",MAX(0,ROUND(($I7-$H7)*1440,0)-N($J7))) | L7: No
A8: 46301 | B8: Aisyah Binti Rahman | C8: M1 | D8: =IF($A8="","",3+INT(($A8-DATE(2026,10,5))/7)) | E8: STRAT | F8: T02 | G8: SYSTEM - Launch meeting, cycle strategy and stack decisions | H8: 0.55763889 | I8: 0.64097222 | J8: 0 | K8: =IF(OR($H8="",$I8=""),"",MAX(0,ROUND(($I8-$H8)*1440,0)-N($J8))) | L8: No
A9: 46302 | B9: Aisyah Binti Rahman | C9: M1 | D9: =IF($A9="","",3+INT(($A9-DATE(2026,10,5))/7)) | E9: PLAN | F9: T03 | G9: SYSTEM - Task and schedule plan for the cycle | H9: 0.51041667 | I9: 0.59861111 | J9: 0 | K9: =IF(OR($H9="",$I9=""),"",MAX(0,ROUND(($I9-$H9)*1440,0)-N($J9))) | L9: No
A10: 46310 | B10: Aisyah Binti Rahman | C10: M1 | D10: =IF($A10="","",3+INT(($A10-DATE(2026,10,5))/7)) | E10: REQ | F10: T04 | G10: SYSTEM - Elicit requirements from SeaFresh and write the SRS | H10: 0.33333333 | I10: 0.36875 | J10: 0 | K10: =IF(OR($H10="",$I10=""),"",MAX(0,ROUND(($I10-$H10)*1440,0)-N($J10))) | L10: No
A11: 46311 | B11: Aisyah Binti Rahman | C11: M1 | D11: =IF($A11="","",3+INT(($A11-DATE(2026,10,5))/7)) | E11: REQINSP | F11: T06 | G11: SYSTEM - Team inspection of the SRS | H11: 0.46527778 | I11: 0.53472222 | J11: 0 | K11: =IF(OR($H11="",$I11=""),"",MAX(0,ROUND(($I11-$H11)*1440,0)-N($J11))) | L11: No
A12: 46312 | B12: Aisyah Binti Rahman | C12: M1 | D12: =IF($A12="","",3+INT(($A12-DATE(2026,10,5))/7)) | E12: HLD | F12: T07 | G12: SYSTEM - Architecture and SDD | H12: 0.41666667 | I12: 0.45486111 | J12: 0 | K12: =IF(OR($H12="",$I12=""),"",MAX(0,ROUND(($I12-$H12)*1440,0)-N($J12))) | L12: No
A13: 46307 | B13: Aisyah Binti Rahman | C13: M1 | D13: =IF($A13="","",3+INT(($A13-DATE(2026,10,5))/7)) | E13: HLDINSP | F13: T09 | G13: SYSTEM - Team inspection of the SDD | H13: 0.375 | I13: 0.40833333 | J13: 0 | K13: =IF(OR($H13="",$I13=""),"",MAX(0,ROUND(($I13-$H13)*1440,0)-N($J13))) | L13: No
A14: 46315 | B14: Aisyah Binti Rahman | C14: M1 | D14: =IF($A14="","",3+INT(($A14-DATE(2026,10,5))/7)) | E14: DLDR | F14: T11 | G14: UI / screens - Personal review of the detailed design | H14: 0.59027778 | I14: 0.67361111 | J14: 0 | K14: =IF(OR($H14="",$I14=""),"",MAX(0,ROUND(($I14-$H14)*1440,0)-N($J14))) | L14: No
A15: 46316 | B15: Aisyah Binti Rahman | C15: M1 | D15: =IF($A15="","",3+INT(($A15-DATE(2026,10,5))/7)) | E15: TD | F15: T12 | G15: UI / screens - Write the test cases for this component | H15: 0.625 | I15: 0.70625 | J15: 0 | K15: =IF(OR($H15="",$I15=""),"",MAX(0,ROUND(($I15-$H15)*1440,0)-N($J15))) | L15: No
A16: 46317 | B16: Aisyah Binti Rahman | C16: M1 | D16: =IF($A16="","",3+INT(($A16-DATE(2026,10,5))/7)) | E16: DLDINSP | F16: T13 | G16: UI / screens - Team inspection of the detailed design | H16: 0.40625 | I16: 0.44097222 | J16: 0 | K16: =IF(OR($H16="",$I16=""),"",MAX(0,ROUND(($I16-$H16)*1440,0)-N($J16))) | L16: No
A17: 46325 | B17: Aisyah Binti Rahman | C17: M2 | D17: =IF($A17="","",3+INT(($A17-DATE(2026,10,5))/7)) | E17: CR | F17: T15 | G17: UI / screens - Pull-request review by a teammate | H17: 0.58333333 | I17: 0.66388889 | J17: 0 | K17: =IF(OR($H17="",$I17=""),"",MAX(0,ROUND(($I17-$H17)*1440,0)-N($J17))) | L17: No
A18: 46326 | B18: Aisyah Binti Rahman | C18: M2 | D18: =IF($A18="","",3+INT(($A18-DATE(2026,10,5))/7)) | E18: CODEINSP | F18: T17 | G18: UI / screens - Team code inspection | H18: 0.375 | I18: 0.44930556 | J18: 0 | K18: =IF(OR($H18="",$I18=""),"",MAX(0,ROUND(($I18-$H18)*1440,0)-N($J18))) | L18: No
... A31: 46300 | B31: Daniel Wong Jun Hao | C31: M1 | D31: =IF($A31="","",3+INT(($A31-DATE(2026,10,5))/7)) | E31: STRAT | F31: T02 | G31: SYSTEM - Launch meeting, cycle strategy and stack decisions | H31: 0.42013889 | I31: 0.46180556 | J31: 0 | K31: =IF(OR($H31="",$I31=""),"",MAX(0,ROUND(($I31-$H31)*1440,0)-N($J31))) | L31: No
A32: 46301 | B32: Daniel Wong Jun Hao | C32: M1 | D32: =IF($A32="","",3+INT(($A32-DATE(2026,10,5))/7)) | E32: PLAN | F32: T03 | G32: SYSTEM - Task and schedule plan for the cycle | H32: 0.39930556 | I32: 0.47222222 | J32: 15 | K32: =IF(OR($H32="",$I32=""),"",MAX(0,ROUND(($I32-$H32)*1440,0)-N($J32))) | L32: No | M32: eat breakfast
A33: 46309 | B33: Daniel Wong Jun Hao | C33: M1 | D33: =IF($A33="","",3+INT(($A33-DATE(2026,10,5))/7)) | E33: REQ | F33: T04 | G33: SYSTEM - Elicit requirements from SeaFresh and write the SRS | H33: 0.48611111 | I33: 0.56944444 | J33: 0 | K33: =IF(OR($H33="",$I33=""),"",MAX(0,ROUND(($I33-$H33)*1440,0)-N($J33))) | L33: No
