Workbook

Sheet README
A1: My TSPi Workbook - TMA3084 Software Engineering Laboratory
A2: Faculty of Computer Science & Information Technology, UNIMAS | Semester 1, Session 2026/2027 | Member workbook v3.0
B4: What this is | C4: Your own copy of the TSPi workbook. You record your work here - your time, your defects, your tests, your AI-assisted changes - and nobody else types in this file.
B5: How it fits together | C5: Your team also keeps one master workbook. Once a week, at the team meeting, you open the EXPORT sheet here and paste its numbers into your row on the master's TEAM sheet, then paste your log rows into the master's shared logs. That is the whole handover.
B6: Fill in SETUP first | C6: Your name and matric number on SETUP are what the EXPORT sheet stamps onto your numbers, so the team can tell whose row is whose.
B7: Colour convention | C7: AMBER cells are yours to fill in. GREY cells are calculated - typing over one breaks the summary that depends on it.
B8: The honest bit | C8: This file is the evidence behind your individual mark. Logging work you did not do is academic dishonesty, and because the master cross-checks your reported hours against the rows you paste in, a workbook that disagrees with itself is visible immediately.
A10: The weekly routine
C11: Every working session: start a LOGT row when you sit down, close it when you get up.
C12: Every defect you fix: a LOGD row, with the phase the mistake was made in.
C13: Every test you run: a LOGTEST row.
C14: Every AI-assisted change: a LOGAI row, with a teammate named as reviewer.
C15: Every week at the meeting: open EXPORT, paste into the master, done.

Sheet SETUP
A1: My Details
A2: Fill this once. Everything else in this workbook reads from here.
A4: Member
B5: Full name
B6: Matric number
B7: Team
B8: Project
B9: Course | C9: TMA3084 Software Engineering Laboratory
B10: Semester | C10: Semester 1, Session 2026/2027
B11: Instructor | C11: Ts. Nurfauza Jali
A13: My commitment
B14: Hours per week I am committing to | C14: 10
B15: My main role this cycle
B16: My second role, if I have one

Sheet MYTASK
A1: My Task Plan
A2: Only the tasks you own. Actual hours arrive from LOGT by themselves.
A4: Member | B4: =SETUP!$C$5 | E4: My tasks | F4: =COUNTA(MYTASK!$A$8:$A$87) | G4: Plan hrs | H4: =SUM(MYTASK!$F$8:$F$87) | I4: Actual hrs | J4: =SUM(MYTASK!$H$8:$H$87) | K4: Complete | L4: =COUNTIF(MYTASK!$J$8:$J$87,"Complete")
A7: Task ID | B7: M/stone | C7: Phase | D7: Component | E7: Task | F7: Plan hrs | G7: Plan wk | H7: Actual hrs | I7: Act. wk | J7: Status | K7: Plan value | L7: Earned value
H8: =IF($A8="","",SUMIFS(LOGT!$I$7:$I$206,LOGT!$D$7:$D$206,$A8)/60) | I8: =IFERROR(IF(N($H8)=0,"",3+INT((SUMPRODUCT(MAX((LOGT!$D$7:$D$206=$A8)*LOGT!$A$7:$A$206))-DATE(2026,10,5))/7)),"") | K8: =IF(OR($A8="",SUM(MYTASK!$F$8:$F$87)=0),"",$F8/SUM(MYTASK!$F$8:$F$87)) | L8: =IF($A8="","",IF($J8="Complete",$K8,0))
H9: =IF($A9="","",SUMIFS(LOGT!$I$7:$I$206,LOGT!$D$7:$D$206,$A9)/60) | I9: =IFERROR(IF(N($H9)=0,"",3+INT((SUMPRODUCT(MAX((LOGT!$D$7:$D$206=$A9)*LOGT!$A$7:$A$206))-DATE(2026,10,5))/7)),"") | K9: =IF(OR($A9="",SUM(MYTASK!$F$8:$F$87)=0),"",$F9/SUM(MYTASK!$F$8:$F$87)) | L9: =IF($A9="","",IF($J9="Complete",$K9,0))
H10: =IF($A10="","",SUMIFS(LOGT!$I$7:$I$206,LOGT!$D$7:$D$206,$A10)/60) | I10: =IFERROR(IF(N($H10)=0,"",3+INT((SUMPRODUCT(MAX((LOGT!$D$7:$D$206=$A10)*LOGT!$A$7:$A$206))-DATE(2026,10,5))/7)),"") | K10: =IF(OR($A10="",SUM(MYTASK!$F$8:$F$87)=0),"",$F10/SUM(MYTASK!$F$8:$F$87)) | L10: =IF($A10="","",IF($J10="Complete",$K10,0))
H11: =IF($A11="","",SUMIFS(LOGT!$I$7:$I$206,LOGT!$D$7:$D$206,$A11)/60) | I11: =IFERROR(IF(N($H11)=0,"",3+INT((SUMPRODUCT(MAX((LOGT!$D$7:$D$206=$A11)*LOGT!$A$7:$A$206))-DATE(2026,10,5))/7)),"") | K11: =IF(OR($A11="",SUM(MYTASK!$F$8:$F$87)=0),"",$F11/SUM(MYTASK!$F$8:$F$87)) | L11: =IF($A11="","",IF($J11="Complete",$K11,0))
H12: =IF($A12="","",SUMIFS(LOGT!$I$7:$I$206,LOGT!$D$7:$D$206,$A12)/60) | I12: =IFERROR(IF(N($H12)=0,"",3+INT((SUMPRODUCT(MAX((LOGT!$D$7:$D$206=$A12)*LOGT!$A$7:$A$206))-DATE(2026,10,5))/7)),"") | K12: =IF(OR($A12="",SUM(MYTASK!$F$8:$F$87)=0),"",$F12/SUM(MYTASK!$F$8:$F$87)) | L12: =IF($A12="","",IF($J12="Complete",$K12,0))
H13: =IF($A13="","",SUMIFS(LOGT!$I$7:$I$206,LOGT!$D$7:$D$206,$A13)/60) | I13: =IFERROR(IF(N($H13)=0,"",3+INT((SUMPRODUCT(MAX((LOGT!$D$7:$D$206=$A13)*LOGT!$A$7:$A$206))-DATE(2026,10,5))/7)),"") | K13: =IF(OR($A13="",SUM(MYTASK!$F$8:$F$87)=0),"",$F13/SUM(MYTASK!$F$8:$F$87)) | L13: =IF($A13="","",IF($J13="Complete",$K13,0))
H14: =IF($A14="","",SUMIFS(LOGT!$I$7:$I$206,LOGT!$D$7:$D$206,$A14)/60) | I14: =IFERROR(IF(N($H14)=0,"",3+INT((SUMPRODUCT(MAX((LOGT!$D$7:$D$206=$A14)*LOGT!$A$7:$A$206))-DATE(2026,10,5))/7)),"") | K14: =IF(OR($A14="",SUM(MYTASK!$F$8:$F$87)=0),"",$F14/SUM(MYTASK!$F$8:$F$87)) | L14: =IF($A14="","",IF($J14="Complete",$K14,0))
H15: =IF($A15="","",SUMIFS(LOGT!$I$7:$I$206,LOGT!$D$7:$D$206,$A15)/60) | I15: =IFERROR(IF(N($H15)=0,"",3+INT((SUMPRODUCT(MAX((LOGT!$D$7:$D$206=$A15)*LOGT!$A$7:$A$206))-DATE(2026,10,5))/7)),"") | K15: =IF(OR($A15="",SUM(MYTASK!$F$8:$F$87)=0),"",$F15/SUM(MYTASK!$F$8:$F$87)) | L15: =IF($A15="","",IF($J15="Complete",$K15,0))
H16: =IF($A16="","",SUMIFS(LOGT!$I$7:$I$206,LOGT!$D$7:$D$206,$A16)/60) | I16: =IFERROR(IF(N($H16)=0,"",3+INT((SUMPRODUCT(MAX((LOGT!$D$7:$D$206=$A16)*LOGT!$A$7:$A$206))-DATE(2026,10,5))/7)),"") | K16: =IF(OR($A16="",SUM(MYTASK!$F$8:$F$87)=0),"",$F16/SUM(MYTASK!$F$8:$F$87)) | L16: =IF($A16="","",IF($J16="Complete",$K16,0))
H17: =IF($A17="","",SUMIFS(LOGT!$I$7:$I$206,LOGT!$D$7:$D$206,$A17)/60) | I17: =IFERROR(IF(N($H17)=0,"",3+INT((SUMPRODUCT(MAX((LOGT!$D$7:$D$206=$A17)*LOGT!$A$7:$A$206))-DATE(2026,10,5))/7)),"") | K17: =IF(OR($A17="",SUM(MYTASK!$F$8:$F$87)=0),"",$F17/SUM(MYTASK!$F$8:$F$87)) | L17: =IF($A17="","",IF($J17="Complete",$K17,0))
H18: =IF($A18="","",SUMIFS(LOGT!$I$7:$I$206,LOGT!$D$7:$D$206,$A18)/60) | I18: =IFERROR(IF(N($H18)=0,"",3+INT((SUMPRODUCT(MAX((LOGT!$D$7:$D$206=$A18)*LOGT!$A$7:$A$206))-DATE(2026,10,5))/7)),"") | K18: =IF(OR($A18="",SUM(MYTASK!$F$8:$F$87)=0),"",$F18/SUM(MYTASK!$F$8:$F$87)) | L18: =IF($A18="","",IF($J18="Complete",$K18,0))
H19: =IF($A19="","",SUMIFS(LOGT!$I$7:$I$206,LOGT!$D$7:$D$206,$A19)/60) | I19: =IFERROR(IF(N($H19)=0,"",3+INT((SUMPRODUCT(MAX((LOGT!$D$7:$D$206=$A19)*LOGT!$A$7:$A$206))-DATE(2026,10,5))/7)),"") | K19: =IF(OR($A19="",SUM(MYTASK!$F$8:$F$87)=0),"",$F19/SUM(MYTASK!$F$8:$F$87)) | L19: =IF($A19="","",IF($J19="Complete",$K19,0))
... H87: =IF($A87="","",SUMIFS(LOGT!$I$7:$I$206,LOGT!$D$7:$D$206,$A87)/60) | I87: =IFERROR(IF(N($H87)=0,"",3+INT((SUMPRODUCT(MAX((LOGT!$D$7:$D$206=$A87)*LOGT!$A$7:$A$206))-DATE(2026,10,5))/7)),"") | K87: =IF(OR($A87="",SUM(MYTASK!$F$8:$F$87)=0),"",$F87/SUM(MYTASK!$F$8:$F$87)) | L87: =IF($A87="","",IF($J87="Complete",$K87,0))

Sheet MYSCHEDULE
A1: My Weekly Schedule
A2: What you planned to put in each week, against what you actually did.
A4: Member | B4: =SETUP!$C$5 | E4: Task plan hrs | F4: =SUM(MYTASK!$F$8:$F$87) | G4: Schedule hrs | H4: =SUM(C8:C20) | I4: Difference | J4: =H4-F4
A7: Week | B7: Week starting | C7: Plan hrs | D7: Cum plan | E7: Actual hrs | F7: Cum actual | G7: Plan value | H7: Earned value | I7: Cum EV | J7: Comment
A8: 3 | B8: 46300 | D8: =SUM($C$8:$C8) | E8: =SUMIFS(LOGT!$J$7:$J$206,LOGT!$C$7:$C$206,$A8)/60 | F8: =SUM($E$8:$E8) | G8: =SUMIFS(MYTASK!$K$8:$K$87,MYTASK!$G$8:$G$87,$A8) | H8: =SUMIFS(MYTASK!$L$8:$L$87,MYTASK!$I$8:$I$87,$A8) | I8: =SUM($H$8:$H8)
A9: 4 | B9: 46307 | D9: =SUM($C$8:$C9) | E9: =SUMIFS(LOGT!$J$7:$J$206,LOGT!$C$7:$C$206,$A9)/60 | F9: =SUM($E$8:$E9) | G9: =SUMIFS(MYTASK!$K$8:$K$87,MYTASK!$G$8:$G$87,$A9) | H9: =SUMIFS(MYTASK!$L$8:$L$87,MYTASK!$I$8:$I$87,$A9) | I9: =SUM($H$8:$H9)
A10: 5 | B10: 46314 | D10: =SUM($C$8:$C10) | E10: =SUMIFS(LOGT!$J$7:$J$206,LOGT!$C$7:$C$206,$A10)/60 | F10: =SUM($E$8:$E10) | G10: =SUMIFS(MYTASK!$K$8:$K$87,MYTASK!$G$8:$G$87,$A10) | H10: =SUMIFS(MYTASK!$L$8:$L$87,MYTASK!$I$8:$I$87,$A10) | I10: =SUM($H$8:$H10)
A11: 6 | B11: 46321 | D11: =SUM($C$8:$C11) | E11: =SUMIFS(LOGT!$J$7:$J$206,LOGT!$C$7:$C$206,$A11)/60 | F11: =SUM($E$8:$E11) | G11: =SUMIFS(MYTASK!$K$8:$K$87,MYTASK!$G$8:$G$87,$A11) | H11: =SUMIFS(MYTASK!$L$8:$L$87,MYTASK!$I$8:$I$87,$A11) | I11: =SUM($H$8:$H11)
A12: 7 | B12: 46328 | D12: =SUM($C$8:$C12) | E12: =SUMIFS(LOGT!$J$7:$J$206,LOGT!$C$7:$C$206,$A12)/60 | F12: =SUM($E$8:$E12) | G12: =SUMIFS(MYTASK!$K$8:$K$87,MYTASK!$G$8:$G$87,$A12) | H12: =SUMIFS(MYTASK!$L$8:$L$87,MYTASK!$I$8:$I$87,$A12) | I12: =SUM($H$8:$H12)
A13: 8 | B13: 46335 | D13: =SUM($C$8:$C13) | E13: =SUMIFS(LOGT!$J$7:$J$206,LOGT!$C$7:$C$206,$A13)/60 | F13: =SUM($E$8:$E13) | G13: =SUMIFS(MYTASK!$K$8:$K$87,MYTASK!$G$8:$G$87,$A13) | H13: =SUMIFS(MYTASK!$L$8:$L$87,MYTASK!$I$8:$I$87,$A13) | I13: =SUM($H$8:$H13) | J13: Mid-semester break
A14: 9 | B14: 46342 | D14: =SUM($C$8:$C14) | E14: =SUMIFS(LOGT!$J$7:$J$206,LOGT!$C$7:$C$206,$A14)/60 | F14: =SUM($E$8:$E14) | G14: =SUMIFS(MYTASK!$K$8:$K$87,MYTASK!$G$8:$G$87,$A14) | H14: =SUMIFS(MYTASK!$L$8:$L$87,MYTASK!$I$8:$I$87,$A14) | I14: =SUM($H$8:$H14)
A15: 10 | B15: 46349 | D15: =SUM($C$8:$C15) | E15: =SUMIFS(LOGT!$J$7:$J$206,LOGT!$C$7:$C$206,$A15)/60 | F15: =SUM($E$8:$E15) | G15: =SUMIFS(MYTASK!$K$8:$K$87,MYTASK!$G$8:$G$87,$A15) | H15: =SUMIFS(MYTASK!$L$8:$L$87,MYTASK!$I$8:$I$87,$A15) | I15: =SUM($H$8:$H15)
A16: 11 | B16: 46356 | D16: =SUM($C$8:$C16) | E16: =SUMIFS(LOGT!$J$7:$J$206,LOGT!$C$7:$C$206,$A16)/60 | F16: =SUM($E$8:$E16) | G16: =SUMIFS(MYTASK!$K$8:$K$87,MYTASK!$G$8:$G$87,$A16) | H16: =SUMIFS(MYTASK!$L$8:$L$87,MYTASK!$I$8:$I$87,$A16) | I16: =SUM($H$8:$H16)
A17: 12 | B17: 46363 | D17: =SUM($C$8:$C17) | E17: =SUMIFS(LOGT!$J$7:$J$206,LOGT!$C$7:$C$206,$A17)/60 | F17: =SUM($E$8:$E17) | G17: =SUMIFS(MYTASK!$K$8:$K$87,MYTASK!$G$8:$G$87,$A17) | H17: =SUMIFS(MYTASK!$L$8:$L$87,MYTASK!$I$8:$I$87,$A17) | I17: =SUM($H$8:$H17)
A18: 13 | B18: 46370 | D18: =SUM($C$8:$C18) | E18: =SUMIFS(LOGT!$J$7:$J$206,LOGT!$C$7:$C$206,$A18)/60 | F18: =SUM($E$8:$E18) | G18: =SUMIFS(MYTASK!$K$8:$K$87,MYTASK!$G$8:$G$87,$A18) | H18: =SUMIFS(MYTASK!$L$8:$L$87,MYTASK!$I$8:$I$87,$A18) | I18: =SUM($H$8:$H18)
A19: 14 | B19: 46377 | D19: =SUM($C$8:$C19) | E19: =SUMIFS(LOGT!$J$7:$J$206,LOGT!$C$7:$C$206,$A19)/60 | F19: =SUM($E$8:$E19) | G19: =SUMIFS(MYTASK!$K$8:$K$87,MYTASK!$G$8:$G$87,$A19) | H19: =SUMIFS(MYTASK!$L$8:$L$87,MYTASK!$I$8:$I$87,$A19) | I19: =SUM($H$8:$H19)
A20: 15 | B20: 46384 | D20: =SUM($C$8:$C20) | E20: =SUMIFS(LOGT!$J$7:$J$206,LOGT!$C$7:$C$206,$A20)/60 | F20: =SUM($E$8:$E20) | G20: =SUMIFS(MYTASK!$K$8:$K$87,MYTASK!$G$8:$G$87,$A20) | H20: =SUMIFS(MYTASK!$L$8:$L$87,MYTASK!$I$8:$I$87,$A20) | I20: =SUM($H$8:$H20)

Sheet LOGT
A1: Form LOGT - My Time Recording Log
A2: One row per working session. Delta is calculated; never type over it.
A4: Member | B4: =SETUP!$C$5 | E4: Total hours | F4: =SUM(LOGT!$I$7:$I$206)/60 | G4: Sessions | H4: =COUNT(LOGT!$I$7:$I$206)
A6: Date | B6: M/stone | C6: Week | D6: Phase | E6: Task ID | F6: What you worked on | G6: Start | H6: Stop | I6: Interrupt (min) | J6: Delta (min) | K6: Comments
C7: =IF($A7="","",3+INT(($A7-DATE(2026,10,5))/7)) | J7: =IF(OR($G7="",$H7=""),"",MAX(0,ROUND(($H7-$G7)*1440,0)-N($I7)))
C8: =IF($A8="","",3+INT(($A8-DATE(2026,10,5))/7)) | J8: =IF(OR($G8="",$H8=""),"",MAX(0,ROUND(($H8-$G8)*1440,0)-N($I8)))
C9: =IF($A9="","",3+INT(($A9-DATE(2026,10,5))/7)) | J9: =IF(OR($G9="",$H9=""),"",MAX(0,ROUND(($H9-$G9)*1440,0)-N($I9)))
C10: =IF($A10="","",3+INT(($A10-DATE(2026,10,5))/7)) | J10: =IF(OR($G10="",$H10=""),"",MAX(0,ROUND(($H10-$G10)*1440,0)-N($I10)))
C11: =IF($A11="","",3+INT(($A11-DATE(2026,10,5))/7)) | J11: =IF(OR($G11="",$H11=""),"",MAX(0,ROUND(($H11-$G11)*1440,0)-N($I11)))
C12: =IF($A12="","",3+INT(($A12-DATE(2026,10,5))/7)) | J12: =IF(OR($G12="",$H12=""),"",MAX(0,ROUND(($H12-$G12)*1440,0)-N($I12)))
C13: =IF($A13="","",3+INT(($A13-DATE(2026,10,5))/7)) | J13: =IF(OR($G13="",$H13=""),"",MAX(0,ROUND(($H13-$G13)*1440,0)-N($I13)))
C14: =IF($A14="","",3+INT(($A14-DATE(2026,10,5))/7)) | J14: =IF(OR($G14="",$H14=""),"",MAX(0,ROUND(($H14-$G14)*1440,0)-N($I14)))
C15: =IF($A15="","",3+INT(($A15-DATE(2026,10,5))/7)) | J15: =IF(OR($G15="",$H15=""),"",MAX(0,ROUND(($H15-$G15)*1440,0)-N($I15)))
C16: =IF($A16="","",3+INT(($A16-DATE(2026,10,5))/7)) | J16: =IF(OR($G16="",$H16=""),"",MAX(0,ROUND(($H16-$G16)*1440,0)-N($I16)))
C17: =IF($A17="","",3+INT(($A17-DATE(2026,10,5))/7)) | J17: =IF(OR($G17="",$H17=""),"",MAX(0,ROUND(($H17-$G17)*1440,0)-N($I17)))
C18: =IF($A18="","",3+INT(($A18-DATE(2026,10,5))/7)) | J18: =IF(OR($G18="",$H18=""),"",MAX(0,ROUND(($H18-$G18)*1440,0)-N($I18)))
... C206: =IF($A206="","",3+INT(($A206-DATE(2026,10,5))/7)) | J206: =IF(OR($G206="",$H206=""),"",MAX(0,ROUND(($H206-$G206)*1440,0)-N($I206)))

Sheet LOGD
A1: Form LOGD - My Defect Recording Log
A2: Every defect you found and fixed. Injected in is the phase the mistake was MADE.
A4: Member | B4: =SETUP!$C$5 | E4: Defects | F4: =COUNTA(LOGD!$B$7:$B$106) | G4: Fix time (hrs) | I4: =SUM(LOGD!$H$7:$H$106)/60
A6: Date | B6: Defect ID | C6: M/stone | D6: Type | E6: Component | F6: Injected in | G6: Removed in | H6: Fix time (min) | I6: Fix reference | J6: Severity | K6: From AI? | L6: Description & root cause

Sheet LOGTEST
A1: Form LOGTEST - My Test Case Log
A2: Automated tests get a row too.
A4: Member | B4: =SETUP!$C$5 | E4: Cases | F4: =COUNTA(LOGTEST!$B$7:$B$106) | G4: Pass rate | H4: =IFERROR(COUNTIF(LOGTEST!$H$7:$H$106,"Pass")/COUNTA(LOGTEST!$H$7:$H$106),"")
A6: Date run | B6: Test ID | C6: Module / screen | D6: What is being tested | E6: Type | F6: Expected | G6: Actual | H6: Status | I6: M/stone | J6: Defect ref | K6: Automated?

Sheet LOGAI
A1: Form LOGAI - My AI-Assisted Development Log
A2: Every change where a generator wrote code that reached the repository. The reviewer must not be you.
A4: Member | B4: =SETUP!$C$5 | E4: Entries | F4: =COUNTA(LOGAI!$A$7:$A$56) | G4: Lines kept | I4: =SUM(LOGAI!$H$7:$H$56) | J4: Keep rate | L4: =IFERROR(SUM(LOGAI!$H$7:$H$56)/SUM(LOGAI!$G$7:$G$56),"")
A6: Date | B6: M/stone | C6: File / module | D6: Feature | E6: AI tool | F6: Prompt (summarised) | G6: Lines gen. | H6: Lines kept | I6: Keep % | J6: Reviewer | K6: Verdict | L6: Tests? | M6: Test status | N6: Commit / PR ref
I7: =IF(N($G7)=0,"",$H7/$G7)
I8: =IF(N($G8)=0,"",$H8/$G8)
I9: =IF(N($G9)=0,"",$H9/$G9)
I10: =IF(N($G10)=0,"",$H10/$G10)
I11: =IF(N($G11)=0,"",$H11/$G11)
I12: =IF(N($G12)=0,"",$H12/$G12)
I13: =IF(N($G13)=0,"",$H13/$G13)
I14: =IF(N($G14)=0,"",$H14/$G14)
I15: =IF(N($G15)=0,"",$H15/$G15)
I16: =IF(N($G16)=0,"",$H16/$G16)
I17: =IF(N($G17)=0,"",$H17/$G17)
I18: =IF(N($G18)=0,"",$H18/$G18)
... I56: =IF(N($G56)=0,"",$H56/$G56)

Sheet MYSUMP
A1: My Plan Summary
A2: Plan column is yours; actual reads itself out of your logs.
A4: Member | B4: =SETUP!$C$5
A6: Time in Phase (hours)
A7: Phase | B7: Plan | C7: Actual | D7: Actual % | E7: Description
A8: MGMT | B8: =SUMIFS(MYTASK!$F$8:$F$87,MYTASK!$C$8:$C$87,"MGMT") | C8: =SUMIFS(LOGT!$J$7:$J$206,LOGT!$D$7:$D$206,"MGMT")/60 | D8: =IF($C$34=0,"",$C8/$C$34) | E8: Management & Miscellaneous
A9: STRAT | B9: =SUMIFS(MYTASK!$F$8:$F$87,MYTASK!$C$8:$C$87,"STRAT") | C9: =SUMIFS(LOGT!$J$7:$J$206,LOGT!$D$7:$D$206,"STRAT")/60 | D9: =IF($C$34=0,"",$C9/$C$34) | E9: Launch & Strategy
A10: PLAN | B10: =SUMIFS(MYTASK!$F$8:$F$87,MYTASK!$C$8:$C$87,"PLAN") | C10: =SUMIFS(LOGT!$J$7:$J$206,LOGT!$D$7:$D$206,"PLAN")/60 | D10: =IF($C$34=0,"",$C10/$C$34) | E10: Planning
A11: REQ | B11: =SUMIFS(MYTASK!$F$8:$F$87,MYTASK!$C$8:$C$87,"REQ") | C11: =SUMIFS(LOGT!$J$7:$J$206,LOGT!$D$7:$D$206,"REQ")/60 | D11: =IF($C$34=0,"",$C11/$C$34) | E11: Requirements / SRS
A12: STP | B12: =SUMIFS(MYTASK!$F$8:$F$87,MYTASK!$C$8:$C$87,"STP") | C12: =SUMIFS(LOGT!$J$7:$J$206,LOGT!$D$7:$D$206,"STP")/60 | D12: =IF($C$34=0,"",$C12/$C$34) | E12: System Test Plan
A13: REQINSP | B13: =SUMIFS(MYTASK!$F$8:$F$87,MYTASK!$C$8:$C$87,"REQINSP") | C13: =SUMIFS(LOGT!$J$7:$J$206,LOGT!$D$7:$D$206,"REQINSP")/60 | D13: =IF($C$34=0,"",$C13/$C$34) | E13: Requirements Inspection
A14: HLD | B14: =SUMIFS(MYTASK!$F$8:$F$87,MYTASK!$C$8:$C$87,"HLD") | C14: =SUMIFS(LOGT!$J$7:$J$206,LOGT!$D$7:$D$206,"HLD")/60 | D14: =IF($C$34=0,"",$C14/$C$34) | E14: High-Level Design / Architecture (SDD)
A15: ITP | B15: =SUMIFS(MYTASK!$F$8:$F$87,MYTASK!$C$8:$C$87,"ITP") | C15: =SUMIFS(LOGT!$J$7:$J$206,LOGT!$D$7:$D$206,"ITP")/60 | D15: =IF($C$34=0,"",$C15/$C$34) | E15: Integration Test Plan
A16: HLDINSP | B16: =SUMIFS(MYTASK!$F$8:$F$87,MYTASK!$C$8:$C$87,"HLDINSP") | C16: =SUMIFS(LOGT!$J$7:$J$206,LOGT!$D$7:$D$206,"HLDINSP")/60 | D16: =IF($C$34=0,"",$C16/$C$34) | E16: HLD Inspection
A17: DLD | B17: =SUMIFS(MYTASK!$F$8:$F$87,MYTASK!$C$8:$C$87,"DLD") | C17: =SUMIFS(LOGT!$J$7:$J$206,LOGT!$D$7:$D$206,"DLD")/60 | D17: =IF($C$34=0,"",$C17/$C$34) | E17: Detailed Design (screens, widgets, models)
A18: DLDR | B18: =SUMIFS(MYTASK!$F$8:$F$87,MYTASK!$C$8:$C$87,"DLDR") | C18: =SUMIFS(LOGT!$J$7:$J$206,LOGT!$D$7:$D$206,"DLDR")/60 | D18: =IF($C$34=0,"",$C18/$C$34) | E18: Detailed Design Review
A19: TD | B19: =SUMIFS(MYTASK!$F$8:$F$87,MYTASK!$C$8:$C$87,"TD") | C19: =SUMIFS(LOGT!$J$7:$J$206,LOGT!$D$7:$D$206,"TD")/60 | D19: =IF($C$34=0,"",$C19/$C$34) | E19: Test Development
A20: DLDINSP | B20: =SUMIFS(MYTASK!$F$8:$F$87,MYTASK!$C$8:$C$87,"DLDINSP") | C20: =SUMIFS(LOGT!$J$7:$J$206,LOGT!$D$7:$D$206,"DLDINSP")/60 | D20: =IF($C$34=0,"",$C20/$C$34) | E20: Detailed Design Inspection
A21: CODE | B21: =SUMIFS(MYTASK!$F$8:$F$87,MYTASK!$C$8:$C$87,"CODE") | C21: =SUMIFS(LOGT!$J$7:$J$206,LOGT!$D$7:$D$206,"CODE")/60 | D21: =IF($C$34=0,"",$C21/$C$34) | E21: Code - hand-written Dart/Flutter
A22: AIGEN | B22: =SUMIFS(MYTASK!$F$8:$F$87,MYTASK!$C$8:$C$87,"AIGEN") | C22: =SUMIFS(LOGT!$J$7:$J$206,LOGT!$D$7:$D$206,"AIGEN")/60 | D22: =IF($C$34=0,"",$C22/$C$34) | E22: Code - AI-assisted generation (Vibe)
A23: CR | B23: =SUMIFS(MYTASK!$F$8:$F$87,MYTASK!$C$8:$C$87,"CR") | C23: =SUMIFS(LOGT!$J$7:$J$206,LOGT!$D$7:$D$206,"CR")/60 | D23: =IF($C$34=0,"",$C23/$C$34) | E23: Code Review / Pull-Request Review
A24: BUILD | B24: =SUMIFS(MYTASK!$F$8:$F$87,MYTASK!$C$8:$C$87,"BUILD") | C24: =SUMIFS(LOGT!$J$7:$J$206,LOGT!$D$7:$D$206,"BUILD")/60 | D24: =IF($C$34=0,"",$C24/$C$34) | E24: Build & Static Analysis (flutter analyze)
A25: CODEINSP | B25: =SUMIFS(MYTASK!$F$8:$F$87,MYTASK!$C$8:$C$87,"CODEINSP") | C25: =SUMIFS(LOGT!$J$7:$J$206,LOGT!$D$7:$D$206,"CODEINSP")/60 | D25: =IF($C$34=0,"",$C25/$C$34) | E25: Code Inspection
A26: UT | B26: =SUMIFS(MYTASK!$F$8:$F$87,MYTASK!$C$8:$C$87,"UT") | C26: =SUMIFS(LOGT!$J$7:$J$206,LOGT!$D$7:$D$206,"UT")/60 | D26: =IF($C$34=0,"",$C26/$C$34) | E26: Unit Test
A27: WT | B27: =SUMIFS(MYTASK!$F$8:$F$87,MYTASK!$C$8:$C$87,"WT") | C27: =SUMIFS(LOGT!$J$7:$J$206,LOGT!$D$7:$D$206,"WT")/60 | D27: =IF($C$34=0,"",$C27/$C$34) | E27: Widget Test
A28: IT | B28: =SUMIFS(MYTASK!$F$8:$F$87,MYTASK!$C$8:$C$87,"IT") | C28: =SUMIFS(LOGT!$J$7:$J$206,LOGT!$D$7:$D$206,"IT")/60 | D28: =IF($C$34=0,"",$C28/$C$34) | E28: Build & Integration Test
A29: CICD | B29: =SUMIFS(MYTASK!$F$8:$F$87,MYTASK!$C$8:$C$87,"CICD") | C29: =SUMIFS(LOGT!$J$7:$J$206,LOGT!$D$7:$D$206,"CICD")/60 | D29: =IF($C$34=0,"",$C29/$C$34) | E29: CI/CD Pipeline (GitHub Actions)
A30: ST | B30: =SUMIFS(MYTASK!$F$8:$F$87,MYTASK!$C$8:$C$87,"ST") | C30: =SUMIFS(LOGT!$J$7:$J$206,LOGT!$D$7:$D$206,"ST")/60 | D30: =IF($C$34=0,"",$C30/$C$34) | E30: System Test
A31: UAT | B31: =SUMIFS(MYTASK!$F$8:$F$87,MYTASK!$C$8:$C$87,"UAT") | C31: =SUMIFS(LOGT!$J$7:$J$206,LOGT!$D$7:$D$206,"UAT")/60 | D31: =IF($C$34=0,"",$C31/$C$34) | E31: Client Acceptance Test
A32: DOC | B32: =SUMIFS(MYTASK!$F$8:$F$87,MYTASK!$C$8:$C$87,"DOC") | C32: =SUMIFS(LOGT!$J$7:$J$206,LOGT!$D$7:$D$206,"DOC")/60 | D32: =IF($C$34=0,"",$C32/$C$34) | E32: Documentation & User Manual
A33: PM | B33: =SUMIFS(MYTASK!$F$8:$F$87,MYTASK!$C$8:$C$87,"PM") | C33: =SUMIFS(LOGT!$J$7:$J$206,LOGT!$D$7:$D$206,"PM")/60 | D33: =IF($C$34=0,"",$C33/$C$34) | E33: Postmortem
A34: TOTAL | B34: =SUM(B8:B33) | C34: =SUM(C8:C33)
A36: Defects Injected
A37: Phase | B37: Plan | C37: Actual | D37: Actual % | E37: Description
A38: PLAN | C38: =COUNTIFS(LOGD!$F$7:$F$106,"PLAN") | D38: =IF($C$59=0,"",$C38/$C$59) | E38: Planning
A39: REQ | C39: =COUNTIFS(LOGD!$F$7:$F$106,"REQ") | D39: =IF($C$59=0,"",$C39/$C$59) | E39: Requirements / SRS
A40: STP | C40: =COUNTIFS(LOGD!$F$7:$F$106,"STP") | D40: =IF($C$59=0,"",$C40/$C$59) | E40: System Test Plan
A41: REQINSP | C41: =COUNTIFS(LOGD!$F$7:$F$106,"REQINSP") | D41: =IF($C$59=0,"",$C41/$C$59) | E41: Requirements Inspection
A42: HLD | C42: =COUNTIFS(LOGD!$F$7:$F$106,"HLD") | D42: =IF($C$59=0,"",$C42/$C$59) | E42: High-Level Design / Architecture (SDD)
A43: ITP | C43: =COUNTIFS(LOGD!$F$7:$F$106,"ITP") | D43: =IF($C$59=0,"",$C43/$C$59) | E43: Integration Test Plan
...

Sheet MYSUMQ
A1: My Quality Summary
A2: Your own review discipline. These are the numbers the Quality & Test Manager will ask you about.
A4: Member | B4: =SETUP!$C$5
A6: My Measures
A7: Measure | B7: Actual | C7: Guideline | D7: Verdict | E7: Reading
A8: Hours logged | B8: =SUM(LOGT!$J$7:$J$206)/60 | E8: Everything you have recorded this semester.
A9: Defects I found | B9: =COUNTA(LOGD!$B$7:$B$106) | E9: A higher number is better engineering, not worse work.
A10: Defects / KLOC in my code | B10: =IFERROR(COUNTA(LOGD!$B$7:$B$106)/(MYSUMP!$C$88/1000),"") | E10: Needs your LOC on MYSUMP to compute.
A11: Design review / design time | B11: =IFERROR(SUMIFS(LOGT!$J$7:$J$206,LOGT!$D$7:$D$206,"DLDR")/SUMIFS(LOGT!$J$7:$J$206,LOGT!$D$7:$D$206,"DLD"),"") | C11: 0.5 | D11: =IF($B11="","",IF($B11>=$C11,"OK","LOW" )) | E11: Time reviewing your own design against time producing it.
A12: Code review / code time | B12: =IFERROR(SUMIFS(LOGT!$J$7:$J$206,LOGT!$D$7:$D$206,"CR")/(SUMIFS(LOGT!$J$7:$J$206,LOGT!$D$7:$D$206,"CODE")+SUMIFS(LOGT!$J$7:$J$206,LOGT!$D$7:$D$206,"AIGEN")),"") | C12: 0.5 | D12: =IF($B12="","",IF($B12>=$C12,"OK","LOW" )) | E12: Review time against time writing and generating code.
A13: My code review rate (LOC/hr) | B13: =IFERROR(MYSUMP!$C$88/(SUMIFS(LOGT!$J$7:$J$206,LOGT!$D$7:$D$206,"CR")/60),"") | C13: 200 | D13: =IF($B13="","",IF($B13<=$C13,"OK","ACTION")) | E13: Above 200 and you are reading too fast to find anything.
A14: A/FR (appraisal / failure) | B14: =IFERROR((SUMIFS(LOGT!$J$7:$J$206,LOGT!$D$7:$D$206,"DLDR")+SUMIFS(LOGT!$J$7:$J$206,LOGT!$D$7:$D$206,"CR"))/(SUMIFS(LOGT!$J$7:$J$206,LOGT!$D$7:$D$206,"BUILD")+SUMIFS(LOGT!$J$7:$J$206,LOGT!$D$7:$D$206,"UT")+SUMIFS(LOGT!$J$7:$J$206,LOGT!$D$7:$D$206,"WT")),"") | C14: 2 | D14: =IF($B14="","",IF($B14>=$C14,"OK","LOW" )) | E14: Time reviewing against time fixing in test. Below 2 predicts a painful system test.
A15: % of my defects found before test | B15: =IFERROR(COUNTIFS(LOGD!$G$7:$G$106,"DLDR")+COUNTIFS(LOGD!$G$7:$G$106,"DLDINSP")+COUNTIFS(LOGD!$G$7:$G$106,"CR")+COUNTIFS(LOGD!$G$7:$G$106,"CODEINSP"),0)/MAX(1,COUNTA(LOGD!$B$7:$B$106)) | C15: 0.7 | D15: =IF($B15="","",IF($B15>=$C15,"OK","LOW" )) | E15: Caught in review rather than by the machine.
A16: My test pass rate | B16: =IFERROR(COUNTIF(LOGTEST!$H$7:$H$106,"Pass")/COUNTA(LOGTEST!$H$7:$H$106),"") | C16: 0.95 | D16: =IF($B16="","",IF($B16>=$C16,"OK","LOW" ))
A17: My AI keep rate | B17: =IFERROR(SUM(LOGAI!$H$7:$H$56)/SUM(LOGAI!$G$7:$G$56),"") | E17: Lines that survived review. Low is informative, not shameful.
A18: My AI entries with no reviewer | B18: =SUMPRODUCT((LOGAI!$A$7:$A$56<>"")*(LOGAI!$J$7:$J$56="")) | C18: 0 | D18: =IF($B18="","",IF($B18<=$C18,"OK","ACTION")) | E18: Any row here breaks the review rule.
A19: My AI entries I reviewed myself | B19: =SUMPRODUCT((LOGAI!$J$7:$J$56<>"")*(EXACT(LOGAI!$J$7:$J$56,SETUP!$C$5)*1)) | C19: 0 | D19: =IF($B19="","",IF($B19<=$C19,"OK","ACTION")) | E19: Self-review does not count as review.

Sheet EXPORT
A1: EXPORT - what to give the team each week
A2: Copy the amber row, Paste Special > Values into your row on the master's TEAM sheet, columns F to K.
B4: Member | C4: =SETUP!$C$5 | E4: Matric | F4: =SETUP!$C$6
A6: Paste this row into the team master (TEAM sheet, columns F to K)
B7: Plan tasks | C7: Plan hours | D7: Plan weeks | E7: Actual hrs | F7: Defects | G7: Consolidated on | I7: What the team does with it
B8: =COUNTA(MYTASK!$A$8:$A$87) | C8: =SUM(MYTASK!$F$8:$F$87) | D8: =COUNTIF(MYSCHEDULE!$C$8:$C$20,">0") | E8: =SUM(LOGT!$J$7:$J$206)/60 | F8: =COUNTA(LOGD!$B$7:$B$106) | G8: =TODAY()
B10: Plan tasks | C10: How many tasks you own this cycle.
B11: Plan hours | C11: The hours you committed to in MYTASK.
B12: Plan weeks | C12: Weeks you planned to work in.
B13: Actual hrs | C13: Hours you have actually logged. The master checks this against the rows you paste into its LOGT.
B14: Defects | C14: Defects you have recorded.
B15: Consolidated on | C15: Stamps the date so the team can see which rows are stale.
A18: Also paste your log rows
B19: The six numbers above tell the team where you stand. They do not carry your actual rows, and the team's summaries and charts are built from rows, not totals. So in the same sitting, copy your new LOGT, LOGD, LOGTEST and LOGAI rows into the bottom of the matching sheets on the master, and put your name in the Member column there. If the Agrees? cell on the master's TEAM sheet goes green afterwards, you are done.
A21: My standing, at a glance
B22: Measure | C22: Value | I22: Reading
B23: Hours logged | C23: =SUM(LOGT!$J$7:$J$206)/60
B24: Tasks complete | C24: =COUNTIF(MYTASK!$J$8:$J$87,"Complete")&" of "&COUNTA(MYTASK!$A$8:$A$87)
B25: Earned value | C25: =SUM(MYTASK!$L$8:$L$87)
B26: Defects found | C26: =COUNTA(LOGD!$B$7:$B$106)
B27: Tests written | C27: =COUNTA(LOGTEST!$B$7:$B$106)
B28: AI entries | C28: =COUNTA(LOGAI!$A$7:$A$56)

Sheet PHASES
A1: Process Phase Standard
A2: The phase codes you may use in LOGT, LOGD and MYTASK.
A4: Code | B4: Phase | C4: Scope | D4: Size basis
A5: MGMT | B5: Management & Miscellaneous | C5: S | D5: -
A6: STRAT | B6: Launch & Strategy | C6: S | D6: -
A7: PLAN | B7: Planning | C7: S | D7: -
A8: REQ | B8: Requirements / SRS | C8: S | D8: Pages
A9: STP | B9: System Test Plan | C9: S | D9: -
A10: REQINSP | B10: Requirements Inspection | C10: S | D10: Pages
A11: HLD | B11: High-Level Design / Architecture (SDD) | C11: S | D11: Pages
A12: ITP | B12: Integration Test Plan | C12: S | D12: -
A13: HLDINSP | B13: HLD Inspection | C13: S | D13: Pages
A14: DLD | B14: Detailed Design (screens, widgets, models) | C14: P | D14: LOC
A15: DLDR | B15: Detailed Design Review | C15: P | D15: LOC
... A31: PL | B31: Product Life (post-release) | C31: N | D31: LOC

Sheet DEFECTTYPES
A1: Defect Type Standard
A2: The types you may choose in LOGD.
A4: Type | B4: Name | C4: What it covers
A5: 10 | B5: Documentation | C5: Comments, README, API docs, user manual
A6: 20 | B6: Syntax | C6: Dart syntax, spelling, punctuation, typos
A7: 30 | B7: Build / Package | C7: pubspec, dependency conflict, Gradle, signing, build config
A8: 40 | B8: Assignment | C8: Declaration, duplicate names, scope, null-safety misuse
A9: 50 | B9: Interface | C9: Procedure calls, REST/API contract, parameters, serialization
A10: 60 | B10: Checking | C10: Error messages, input validation, inadequate checks
A11: 70 | B11: Data | C11: Structure, content, persistence, local DB / Firestore schema
A12: 80 | B12: Function | C12: Logic, pointers, loops, recursion, computation, business rules
A13: 90 | B13: System | C13: Configuration, timing, memory, platform (iOS/Android) differences
A14: 100 | B14: Environment | C14: Design, compile, test or other support system problems
A15: 110 | B15: UI / Layout | C15: Overflow, responsiveness, theming, accessibility, Material 3 misuse
A16: 120 | B16: State Management | C16: Provider/Riverpod/GetX misuse, rebuild storms, stale or lost state
... A19: 150 | B19: AI-Generated | C19: Defect traced to AI-generated code that passed review unverified

Sheet LISTS
A1: Validation Lists
A2: Source lists for the drop-downs in this workbook.
A4: Phase | B4: Phase description | C4: Defect type | D4: Milestone | E4: Size measure | F4: AI tool | G4: Yes/No | H4: Status | I4: Test type | J4: Severity
A5: MGMT | B5: Management & Miscellaneous | C5: 10 - Documentation | D5: M1 | E5: Dart LOC | F5: GitHub Copilot | G5: Yes | H5: Planned | I5: Unit | J5: Critical
A6: STRAT | B6: Launch & Strategy | C6: 20 - Syntax | D6: M2 | E6: Screens | F6: Claude | G6: No | H6: In progress | I6: Widget | J6: Major
A7: PLAN | B7: Planning | C7: 30 - Build / Package | D7: M3 | E7: Widgets | F7: ChatGPT / GPT-4 | H7: Complete | I7: Integration | J7: Minor
A8: REQ | B8: Requirements / SRS | C8: 40 - Assignment | D8: M4 | E8: API Endpoints | F8: Google Gemini | H8: Carried over | I8: Manual | J8: Cosmetic
A9: STP | B9: System Test Plan | C9: 50 - Interface | E9: Test Cases | F9: Cursor | H9: Cancelled | I9: Acceptance
A10: REQINSP | B10: Requirements Inspection | C10: 60 - Checking | E10: SRS Pages | F10: Other | I10: Regression
A11: HLD | B11: High-Level Design / Architecture (SDD) | C11: 70 - Data | E11: SDD Pages | F11: None | I11: Performance
A12: ITP | B12: Integration Test Plan | C12: 80 - Function | E12: Documents | I12: Security
A13: HLDINSP | B13: HLD Inspection | C13: 90 - System
A14: DLD | B14: Detailed Design (screens, widgets, models) | C14: 100 - Environment
A15: DLDR | B15: Detailed Design Review | C15: 110 - UI / Layout
A16: TD | B16: Test Development | C16: 120 - State Management
A17: DLDINSP | B17: Detailed Design Inspection | C17: 130 - Performance
A18: CODE | B18: Code - hand-written Dart/Flutter | C18: 140 - Security
A19: AIGEN | B19: Code - AI-assisted generation (Vibe) | C19: 150 - AI-Generated
A20: CR | B20: Code Review / Pull-Request Review
A21: BUILD | B21: Build & Static Analysis (flutter analyze)
A22: CODEINSP | B22: Code Inspection
A23: UT | B23: Unit Test
A24: WT | B24: Widget Test
A25: IT | B25: Build & Integration Test
A26: CICD | B26: CI/CD Pipeline (GitHub Actions)
A27: ST | B27: System Test
A28: UAT | B28: Client Acceptance Test
A29: DOC | B29: Documentation & User Manual
A30: PM | B30: Postmortem
A31: PL | B31: Product Life (post-release)
